Workbook

Sheet Dashboard
A1: Play Store PPP Pricing Template
A3: Base Price USD | B3: 1
A4: Global Min USD | B4: 0.49
A5: High PPP Floor USD | B5: 1.99
A6: Default Market Adj | B6: 1
A7: Default FX Source | B7: Manual / Google Sheets formula
A8: Last Updated | B8: 2026-05-01
A9: Notes | B9: Edit yellow cells only. Final price uses PPP + Market Adj + FX + rounding rules.
A10: Output Sheet | B10: PricingModel
A12: How to use | B12: 1) Set Base Price USD in B3 | C12: 2) Edit PPP/Market Adj/FX in PricingModel | D12: 3) Check Final Rounded Local Price | E12: 4) Enter prices manually in Play Console
A14: Tier | B14: PPP Range | C14: Strategy | D14: Typical Use
A15: A | B15: 0.80 - 1.00 | C15: Premium / near full price | D15: US, wealthier EU
A16: B | B16: 0.60 - 0.79 | C16: Slight discount | D16: Strong purchasing power
A17: C | B17: 0.40 - 0.59 | C17: Mid discount | D17: Balanced conversion/revenue
A18: D/E | B18: 0.10 - 0.39 | C18: Aggressive local price | D18: Volume markets

Sheet PricingModel
B1: Country | C1: Country Code | D1: Currency | E1: PPP Factor | F1: Tier | G1: Base USD | H1: PPP Price USD | I1: Market Adj | J1: FX USD→Local | K1: Raw Local Price | L1: Rounding Group | M1: Final Rounded Local | N1: Final USD Approx | O1: Recommended Action | P1: FX Formula for Google Sheets | Q1: Notes
A2: Arnavutluk | B2: Albania | C2: AL | D2: ALL | E2: 0,35 | F2: D | G2: =Dashboard!$B$3 -> 1 | H2: =MAX(Dashboard!$B$4,G2*E2) -> 0.49 | I2: 1 | P2: =GOOGLEFINANCE("CURRENCY:USDALL")
A3: Cezayir | B3: Algeria | C3: DZ | D3: DZD | E3: 0.28 | F3: D | G3: =Dashboard!$B$3 -> 1 | H3: =MAX(Dashboard!$B$4,G3*E3) -> 0.49 | I3: 1
A4: Angola | B4: Angola | C4: AO | D4: AOA | E4: 0.22 | F4: E | G4: =Dashboard!$B$3 -> 1 | H4: =MAX(Dashboard!$B$4,G4*E4) -> 0.49 | I4: 1
A5: Antigua ve Barbuda | B5: Antigua and Barbuda | C5: AG | D5: XCD | E5: 0.65 | F5: B | G5: =Dashboard!$B$3 -> 1 | H5: =MAX(Dashboard!$B$4,G5*E5) -> 0.65 | I5: 1
A6: Arjantin | B6: Argentina | C6: AR | D6: ARS | E6: 0.3 | F6: D | G6: =Dashboard!$B$3 -> 1 | H6: =MAX(Dashboard!$B$4,G6*E6) -> 0.49 | I6: 1
A7: Ermenistan | B7: Armenia | C7: AM | D7: AMD | E7: 0.3 | F7: D | G7: =Dashboard!$B$3 -> 1 | H7: =MAX(Dashboard!$B$4,G7*E7) -> 0.49 | I7: 1
A8: Aruba | B8: Aruba | C8: AW | D8: AWG | E8: 0.75 | F8: B | G8: =Dashboard!$B$3 -> 1 | H8: =MAX(Dashboard!$B$4,G8*E8) -> 0.75 | I8: 1
A9: Avustralya | B9: Australia | C9: AU | D9: AUD | E9: 0.82 | F9: =IF(E9>=0.8,"A",IF(E9>=0.6,"B",IF(E9>=0.4,"C",IF(E9>=0.2,"D","E")))) -> A | G9: =Dashboard!$B$3 -> 1 | H9: =MAX(Dashboard!$B$4,G9*E9) -> 0.82 | I9: 1 | J9: 1.5 | K9: =H9*I9*J9 -> 1.23 | L9: AUD_99 | M9: =IF(L9="TRY_TIERS",IF(K9<25,19,IF(K9<35,29,IF(K9<45,39,IF(K9<60,49,79)))), IF(L9="INR_TIERS",IF(K9<40,29,IF(K9<70,49,99)), IF(L9="BRL_90",IF(K9<3,2.9,IF(K9<6,4.9,IF(K9<10,6.9,9.9))), IF(L9="IDR_000",ROUND(K9/1000,0)*1000, IF(L9="JPY_00",ROUND(K9/100,0)*100, IF(L9="KRW_000",ROUND(K9/1000,0)*1000, IF(L9="VND_000",ROUND(K9/1000,0)*1000, IF(OR(L9="USD_99",L9="EUR_99",L9="GBP_99",L9="CAD_99",L9="AUD_99",L9="PLN_99"),MAX(0.49,ROUND(K9,0)-0.01), IF(L9="MXN_00",ROUND(K9,0),IF(L9="THB_00",ROUND(K9,0),ROUND(K9,2))))))))))) -> 0.99 | N9: =M9/J9 -> 0.66 | O9: =IF(N9<Dashboard!$B$4,"Below global min",IF(AND(E9>=0.8,N9<Dashboard!$B$5),"Raise high-PPP floor","OK")) -> Raise high-PPP floor | P9: =GOOGLEFINANCE("CURRENCY:USDAUD")
A10: Avusturya | B10: Austria | C10: AT | D10: EUR | E10: 0.86 | F10: A | G10: =Dashboard!$B$3 -> 1 | H10: =MAX(Dashboard!$B$4,G10*E10) -> 0.86 | I10: 1
A11: Azerbaycan | B11: Azerbaijan | C11: AZ | D11: AZN | E11: 0.4 | F11: D | G11: =Dashboard!$B$3 -> 1 | H11: =MAX(Dashboard!$B$4,G11*E11) -> 0.49 | I11: 1
A12: Bahamalar | B12: Bahamas | C12: BS | D12: BSD | E12: 0.75 | F12: B | G12: =Dashboard!$B$3 -> 1 | H12: =MAX(Dashboard!$B$4,G12*E12) -> 0.75 | I12: 1
A13: Bahreyn | B13: Bahrain | C13: BH | D13: BHD | E13: 0.85 | F13: A | G13: =Dashboard!$B$3 -> 1 | H13: =MAX(Dashboard!$B$4,G13*E13) -> 0.85 | I13: 1
A14: Bangladeş | B14: Bangladesh | C14: BD | D14: BDT | E14: 0.15 | F14: E | G14: =Dashboard!$B$3 -> 1 | H14: =MAX(Dashboard!$B$4,G14*E14) -> 0.49 | I14: 1
A15: Belarus | B15: Belarus | C15: BY | D15: BYN | E15: 0.4 | F15: D | G15: =Dashboard!$B$3 -> 1 | H15: =MAX(Dashboard!$B$4,G15*E15) -> 0.49 | I15: 1
A16: Belçika | B16: Belgium | C16: BE | D16: EUR | E16: 0.84 | F16: A | G16: =Dashboard!$B$3 -> 1 | H16: =MAX(Dashboard!$B$4,G16*E16) -> 0.84 | I16: 1
A17: Belize | B17: Belize | C17: BZ | D17: BZD | E17: 0.35 | F17: D | G17: =Dashboard!$B$3 -> 1 | H17: =MAX(Dashboard!$B$4,G17*E17) -> 0.49 | I17: 1
A18: Benin | B18: Benin | C18: BJ | D18: XOF | E18: 0.18 | F18: E | G18: =Dashboard!$B$3 -> 1 | H18: =MAX(Dashboard!$B$4,G18*E18) -> 0.49 | I18: 1
A19: Bermuda | B19: Bermuda | C19: BM | D19: BMD | E19: 1 | F19: A | G19: =Dashboard!$B$3 -> 1 | H19: =MAX(Dashboard!$B$4,G19*E19) -> 1 | I19: 1
A20: Bolivya | B20: Bolivia | C20: BO | D20: BOB-BOV | E20: 0.3 | F20: D | G20: =Dashboard!$B$3 -> 1 | H20: =MAX(Dashboard!$B$4,G20*E20) -> 0.49 | I20: 1
A21: Bosna-Hersek | B21: Bosnia and Herzegovina | C21: BA | D21: BAM | E21: 0.45 | F21: C | G21: =Dashboard!$B$3 -> 1 | H21: =MAX(Dashboard!$B$4,G21*E21) -> 0.49 | I21: 1
A22: Botsvana | B22: Botswana | C22: BW | D22: BWP | E22: 0.4 | F22: D | G22: =Dashboard!$B$3 -> 1 | H22: =MAX(Dashboard!$B$4,G22*E22) -> 0.49 | I22: 1
A23: Brezilya | B23: Brazil | C23: BR | D23: BRL | E23: 0.35 | F23: =IF(E23>=0.8,"A",IF(E23>=0.6,"B",IF(E23>=0.4,"C",IF(E23>=0.2,"D","E")))) -> D | G23: =Dashboard!$B$3 -> 1 | H23: =MAX(Dashboard!$B$4,G23*E23) -> 0.49 | I23: 0.85 | J23: 5 | K23: =H23*I23*J23 -> 2.0825 | L23: BRL_90 | M23: =IF(L23="TRY_TIERS",IF(K23<25,19,IF(K23<35,29,IF(K23<45,39,IF(K23<60,49,79)))), IF(L23="INR_TIERS",IF(K23<40,29,IF(K23<70,49,99)), IF(L23="BRL_90",IF(K23<3,2.9,IF(K23<6,4.9,IF(K23<10,6.9,9.9))), IF(L23="IDR_000",ROUND(K23/1000,0)*1000, IF(L23="JPY_00",ROUND(K23/100,0)*100, IF(L23="KRW_000",ROUND(K23/1000,0)*1000, IF(L23="VND_000",ROUND(K23/1000,0)*1000, IF(OR(L23="USD_99",L23="EUR_99",L23="GBP_99",L23="CAD_99",L23="AUD_99",L23="PLN_99"),MAX(0.49,ROUND(K23,0)-0.01), IF(L23="MXN_00",ROUND(K23,0),IF(L23="THB_00",ROUND(K23,0),ROUND(K23,2))))))))))) -> 2.9 | N23: =M23/J23 -> 0.58 | O23: =IF(N23<Dashboard!$B$4,"Below global min",IF(AND(E23>=0.8,N23<Dashboard!$B$5),"Raise high-PPP floor","OK")) -> OK | P23: =GOOGLEFINANCE("CURRENCY:USDBRL")
A24: Bulgaristan | B24: Bulgaria | C24: BG | D24: BGN | E24: 0.4 | F24: D | G24: =Dashboard!$B$3 -> 1 | H24: =MAX(Dashboard!$B$4,G24*E24) -> 0.49 | I24: 1
A25: Burkina Faso | B25: Burkina Faso | C25: BF | D25: XOF | E25: 0.18 | F25: E | G25: =Dashboard!$B$3 -> 1 | H25: =MAX(Dashboard!$B$4,G25*E25) -> 0.49 | I25: 1
A26: Cabo Verde | B26: Cabo Verde | C26: CV | D26: CVE | E26: 0.3 | F26: D | G26: =Dashboard!$B$3 -> 1 | H26: =MAX(Dashboard!$B$4,G26*E26) -> 0.49 | I26: 1
A27: Kamboçya | B27: Cambodia | C27: KH | D27: KHR | E27: 0.2 | F27: E | G27: =Dashboard!$B$3 -> 1 | H27: =MAX(Dashboard!$B$4,G27*E27) -> 0.49 | I27: 1
A28: Kamerun | B28: Cameroon | C28: CM | D28: XAF | E28: 0.12 | F28: E | G28: =Dashboard!$B$3 -> 1 | H28: =MAX(Dashboard!$B$4,G28*E28) -> 0.49 | I28: 1
A29: Kanada | B29: Canada | C29: CA | D29: CAD | E29: 0.85 | F29: =IF(E29>=0.8,"A",IF(E29>=0.6,"B",IF(E29>=0.4,"C",IF(E29>=0.2,"D","E")))) -> A | G29: =Dashboard!$B$3 -> 1 | H29: =MAX(Dashboard!$B$4,G29*E29) -> 0.85 | I29: 1 | J29: 1.35 | K29: =H29*I29*J29 -> 1.1475 | L29: CAD_99 | M29: =IF(L29="TRY_TIERS",IF(K29<25,19,IF(K29<35,29,IF(K29<45,39,IF(K29<60,49,79)))), IF(L29="INR_TIERS",IF(K29<40,29,IF(K29<70,49,99)), IF(L29="BRL_90",IF(K29<3,2.9,IF(K29<6,4.9,IF(K29<10,6.9,9.9))), IF(L29="IDR_000",ROUND(K29/1000,0)*1000, IF(L29="JPY_00",ROUND(K29/100,0)*100, IF(L29="KRW_000",ROUND(K29/1000,0)*1000, IF(L29="VND_000",ROUND(K29/1000,0)*1000, IF(OR(L29="USD_99",L29="EUR_99",L29="GBP_99",L29="CAD_99",L29="AUD_99",L29="PLN_99"),MAX(0.49,ROUND(K29,0)-0.01), IF(L29="MXN_00",ROUND(K29,0),IF(L29="THB_00",ROUND(K29,0),ROUND(K29,2))))))))))) -> 0.99 | N29: =M29/J29 -> 0.73333333 | O29: =IF(N29<Dashboard!$B$4,"Below global min",IF(AND(E29>=0.8,N29<Dashboard!$B$5),"Raise high-PPP floor","OK")) -> Raise high-PPP floor | P29: =GOOGLEFINANCE("CURRENCY:USDCAD")
A30: Cayman Adaları | B30: Cayman Islands | C30: KY | D30: KYD | E30: 1 | F30: A | G30: =Dashboard!$B$3 -> 1 | H30: =MAX(Dashboard!$B$4,G30*E30) -> 1 | I30: 1
A31: Orta Afrika Cumhuriyeti | B31: Central African Republic | C31: CF | D31: XAF | E31: 0.12 | F31: E | G31: =Dashboard!$B$3 -> 1 | H31: =MAX(Dashboard!$B$4,G31*E31) -> 0.49 | I31: 1
A32: Çad | B32: Chad | C32: TD | D32: XAF | E32: 0.12 | F32: E | G32: =Dashboard!$B$3 -> 1 | H32: =MAX(Dashboard!$B$4,G32*E32) -> 0.49 | I32: 1
A33: Şili | B33: Chile | C33: CL | D33: CLP | E33: 0.6 | F33: C | G33: =Dashboard!$B$3 -> 1 | H33: =MAX(Dashboard!$B$4,G33*E33) -> 0.6 | I33: 1
A34: Kolombiya | B34: Colombia | C34: CO | D34: COP-COU | E34: 0.38 | F34: D | G34: =Dashboard!$B$3 -> 1 | H34: =MAX(Dashboard!$B$4,G34*E34) -> 0.49 | I34: 1
A35: Komorlar | B35: Comoros | C35: KM | D35: KMF | E35: 0.18 | F35: E | G35: =Dashboard!$B$3 -> 1 | H35: =MAX(Dashboard!$B$4,G35*E35) -> 0.49 | I35: 1
A36: Kongo-Brazavil | B36: Congo | C36: CG | D36: XAF | E36: 0.22 | F36: E | G36: =Dashboard!$B$3 -> 1 | H36: =MAX(Dashboard!$B$4,G36*E36) -> 0.49 | I36: 1
A37: Kongo-Kinşasa | B37: Congo (the Democratic Republic of the) | C37: CD | D37: CDF | E37: 0.15 | F37: E | G37: =Dashboard!$B$3 -> 1 | H37: =MAX(Dashboard!$B$4,G37*E37) -> 0.49 | I37: 1
A38: KostaRika | B38: Costa Rica | C38: CR | D38: CRC | E38: 0.5 | F38: C | G38: =Dashboard!$B$3 -> 1 | H38: =MAX(Dashboard!$B$4,G38*E38) -> 0.5 | I38: 1
A39: Côte d’Ivoire | B39: Côte d’Ivoire | C39: CI | D39: XOF | E39: 0.25 | F39: E | G39: =Dashboard!$B$3 -> 1 | H39: =MAX(Dashboard!$B$4,G39*E39) -> 0.49 | I39: 1
A40: Hırvatistan | B40: Croaita | C40: HR | D40: EUR | E40: 0.55 | F40: C | G40: =Dashboard!$B$3 -> 1 | H40: =MAX(Dashboard!$B$4,G40*E40) -> 0.55 | I40: 1
...

Sheet RoundingRules
A1: Rounding Rules / Editable Playbook
A3: Group | B3: Currency | C3: Logic | D3: Suggested Tiers | E3: Edit Note
A4: USD_99 | B4: USD | C4: Round to x.99 | D4: 0.99 / 1.99 / 2.99 / 3.99 / 4.99 | E4: Good for US-style pricing
A5: EUR_99 | B5: EUR | C5: Round to x.99 | D5: 0.99 / 1.99 / 2.99 / 3.99 / 4.99 | E5: EU premium-friendly
A6: TRY_TIERS | B6: TRY | C6: Fixed tier bucket | D6: 19 / 29 / 39 / 49 / 79 | E6: Test 29 vs 39 for conversion/revenue
A7: INR_TIERS | B7: INR | C7: Fixed tier bucket | D7: 29 / 49 / 99 | E7: Volume market
A8: BRL_90 | B8: BRL | C8: Round to x.90 | D8: 2.90 / 4.90 / 6.90 / 9.90
A9: IDR_000 | B9: IDR | C9: Nearest 1,000 | D9: 9,000 / 15,000 / 29,000
A10: JPY_00 | B10: JPY | C10: Nearest 100 | D10: 100 / 200 / 300 / 500
A11: KRW_000 | B11: KRW | C11: Nearest 1,000 | D11: 1,000 / 2,000 / 3,000 / 5,000
A12: VND_000 | B12: VND | C12: Nearest 1,000 | D12: 10,000 / 20,000 / 30,000

Sheet SourceNotes
A1: Source Notes / References
A3: Input | B3: Purpose | C3: Source / URL | D3: Refresh Cadence | E3: Notes
A4: PPP factor | B4: Relative local affordability input | C4: https://data.worldbank.org/indicator/PA.NUS.PPP | D4: Quarterly or before price updates | E4: Template values are starter estimates; replace with your chosen normalized PPP factors.
A5: FX rate | B5: Convert USD to local currency | C5: https://www.google.com/finance/ | D5: Before Play Console update | E5: In Google Sheets, use GOOGLEFINANCE formulas copied from PricingModel column N.
A6: Google Play pricing | B6: Check supported local prices and taxes | C6: https://support.google.com/googleplay/android-developer/ | D6: Before launch and major updates | E6: Play Console final local prices may differ due to tax/minimum price constraints.
A7: Competitor pricing | B7: Market adjustment sanity check | C7: Manual Play Store research | D7: Before launch | E7: Use Market Adj column to shift price after checking similar apps.

Sheet AB_TEST
A1: Date | B1: App | C1: Country | D1: Variant | E1: Price | F1: Currency | G1: Impressions | H1: Purchases | I1: Conversion | J1: Revenue | K1: ARPU | L1: Winner Note
A2: 46143 | B2: BLE Scanner | C2: TR | D2: A | E2: 39 | F2: TRY | G2: 1200 | H2: 48 | I2: =IFERROR(H2/G2,0) -> 0.04 | J2: =IFERROR(E2*H2,0) -> 1872 | K2: =IFERROR(J2/G2,0) -> 1.56 | L2: =IF(B2="","",IF(J2=MAX(SUMIFS($J$2:$J$200,$B$2:$B$200,B2,$C$2:$C$200,C2,$D$2:$D$200,"A"),SUMIFS($J$2:$J$200,$B$2:$B$200,B2,$C$2:$C$200,C2,$D$2:$D$200,"B")),"Current Winner",""))
A3: 46150 | B3: BLE Scanner | C3: TR | D3: B | E3: 29 | F3: TRY | G3: 1350 | H3: 78 | I3: =IFERROR(H3/G3,0) -> 0.057777778 | J3: =IFERROR(E3*H3,0) -> 2262 | K3: =IFERROR(J3/G3,0) -> 1.6755556 | L3: =IF(B3="","",IF(J3=MAX(SUMIFS($J$2:$J$200,$B$2:$B$200,B3,$C$2:$C$200,C3,$D$2:$D$200,"A"),SUMIFS($J$2:$J$200,$B$2:$B$200,B3,$C$2:$C$200,C3,$D$2:$D$200,"B")),"Current Winner","")) -> Current Winner
A4: 46143 | B4: Secure Vault | C4: TR | D4: A | E4: 49 | F4: TRY | G4: 900 | H4: 32 | I4: =IFERROR(H4/G4,0) -> 0.035555556 | J4: =IFERROR(E4*H4,0) -> 1568 | K4: =IFERROR(J4/G4,0) -> 1.7422222 | L4: =IF(B4="","",IF(J4=MAX(SUMIFS($J$2:$J$200,$B$2:$B$200,B4,$C$2:$C$200,C4,$D$2:$D$200,"A"),SUMIFS($J$2:$J$200,$B$2:$B$200,B4,$C$2:$C$200,C4,$D$2:$D$200,"B")),"Current Winner",""))
A5: 46150 | B5: Secure Vault | C5: TR | D5: B | E5: 39 | F5: TRY | G5: 960 | H5: 45 | I5: =IFERROR(H5/G5,0) -> 0.046875 | J5: =IFERROR(E5*H5,0) -> 1755 | K5: =IFERROR(J5/G5,0) -> 1.828125 | L5: =IF(B5="","",IF(J5=MAX(SUMIFS($J$2:$J$200,$B$2:$B$200,B5,$C$2:$C$200,C5,$D$2:$D$200,"A"),SUMIFS($J$2:$J$200,$B$2:$B$200,B5,$C$2:$C$200,C5,$D$2:$D$200,"B")),"Current Winner","")) -> Current Winner
A6: 46143 | B6: BLE Scanner | C6: IN | D6: A | E6: 49 | F6: INR | G6: 2400 | H6: 96 | I6: =IFERROR(H6/G6,0) -> 0.04 | J6: =IFERROR(E6*H6,0) -> 4704 | K6: =IFERROR(J6/G6,0) -> 1.96 | L6: =IF(B6="","",IF(J6=MAX(SUMIFS($J$2:$J$200,$B$2:$B$200,B6,$C$2:$C$200,C6,$D$2:$D$200,"A"),SUMIFS($J$2:$J$200,$B$2:$B$200,B6,$C$2:$C$200,C6,$D$2:$D$200,"B")),"Current Winner",""))
A7: 46150 | B7: BLE Scanner | C7: IN | D7: B | E7: 29 | F7: INR | G7: 2700 | H7: 168 | I7: =IFERROR(H7/G7,0) -> 0.062222222 | J7: =IFERROR(E7*H7,0) -> 4872 | K7: =IFERROR(J7/G7,0) -> 1.8044444 | L7: =IF(B7="","",IF(J7=MAX(SUMIFS($J$2:$J$200,$B$2:$B$200,B7,$C$2:$C$200,C7,$D$2:$D$200,"A"),SUMIFS($J$2:$J$200,$B$2:$B$200,B7,$C$2:$C$200,C7,$D$2:$D$200,"B")),"Current Winner","")) -> Current Winner
A8: 46143 | B8: Secure Vault | C8: BR | D8: A | E8: 6.9 | F8: BRL | G8: 760 | H8: 20 | I8: =IFERROR(H8/G8,0) -> 0.026315789 | J8: =IFERROR(E8*H8,0) -> 138 | K8: =IFERROR(J8/G8,0) -> 0.18157895 | L8: =IF(B8="","",IF(J8=MAX(SUMIFS($J$2:$J$200,$B$2:$B$200,B8,$C$2:$C$200,C8,$D$2:$D$200,"A"),SUMIFS($J$2:$J$200,$B$2:$B$200,B8,$C$2:$C$200,C8,$D$2:$D$200,"B")),"Current Winner",""))
A9: 46150 | B9: Secure Vault | C9: BR | D9: B | E9: 4.9 | F9: BRL | G9: 830 | H9: 32 | I9: =IFERROR(H9/G9,0) -> 0.038554217 | J9: =IFERROR(E9*H9,0) -> 156.8 | K9: =IFERROR(J9/G9,0) -> 0.18891566 | L9: =IF(B9="","",IF(J9=MAX(SUMIFS($J$2:$J$200,$B$2:$B$200,B9,$C$2:$C$200,C9,$D$2:$D$200,"A"),SUMIFS($J$2:$J$200,$B$2:$B$200,B9,$C$2:$C$200,C9,$D$2:$D$200,"B")),"Current Winner","")) -> Current Winner
I10: =IFERROR(H10/G10,0) -> 0 | J10: =IFERROR(E10*H10,0) -> 0 | K10: =IFERROR(J10/G10,0) -> 0 | L10: =IF(B10="","",IF(J10=MAX(SUMIFS($J$2:$J$200,$B$2:$B$200,B10,$C$2:$C$200,C10,$D$2:$D$200,"A"),SUMIFS($J$2:$J$200,$B$2:$B$200,B10,$C$2:$C$200,C10,$D$2:$D$200,"B")),"Current Winner",""))
I11: =IFERROR(H11/G11,0) -> 0 | J11: =IFERROR(E11*H11,0) -> 0 | K11: =IFERROR(J11/G11,0) -> 0 | L11: =IF(B11="","",IF(J11=MAX(SUMIFS($J$2:$J$200,$B$2:$B$200,B11,$C$2:$C$200,C11,$D$2:$D$200,"A"),SUMIFS($J$2:$J$200,$B$2:$B$200,B11,$C$2:$C$200,C11,$D$2:$D$200,"B")),"Current Winner",""))
I12: =IFERROR(H12/G12,0) -> 0 | J12: =IFERROR(E12*H12,0) -> 0 | K12: =IFERROR(J12/G12,0) -> 0 | L12: =IF(B12="","",IF(J12=MAX(SUMIFS($J$2:$J$200,$B$2:$B$200,B12,$C$2:$C$200,C12,$D$2:$D$200,"A"),SUMIFS($J$2:$J$200,$B$2:$B$200,B12,$C$2:$C$200,C12,$D$2:$D$200,"B")),"Current Winner",""))
I13: =IFERROR(H13/G13,0) -> 0 | J13: =IFERROR(E13*H13,0) -> 0 | K13: =IFERROR(J13/G13,0) -> 0 | L13: =IF(B13="","",IF(J13=MAX(SUMIFS($J$2:$J$200,$B$2:$B$200,B13,$C$2:$C$200,C13,$D$2:$D$200,"A"),SUMIFS($J$2:$J$200,$B$2:$B$200,B13,$C$2:$C$200,C13,$D$2:$D$200,"B")),"Current Winner",""))
I14: =IFERROR(H14/G14,0) -> 0 | J14: =IFERROR(E14*H14,0) -> 0 | K14: =IFERROR(J14/G14,0) -> 0 | L14: =IF(B14="","",IF(J14=MAX(SUMIFS($J$2:$J$200,$B$2:$B$200,B14,$C$2:$C$200,C14,$D$2:$D$200,"A"),SUMIFS($J$2:$J$200,$B$2:$B$200,B14,$C$2:$C$200,C14,$D$2:$D$200,"B")),"Current Winner",""))
I15: =IFERROR(H15/G15,0) -> 0 | J15: =IFERROR(E15*H15,0) -> 0 | K15: =IFERROR(J15/G15,0) -> 0 | L15: =IF(B15="","",IF(J15=MAX(SUMIFS($J$2:$J$200,$B$2:$B$200,B15,$C$2:$C$200,C15,$D$2:$D$200,"A"),SUMIFS($J$2:$J$200,$B$2:$B$200,B15,$C$2:$C$200,C15,$D$2:$D$200,"B")),"Current Winner",""))
I16: =IFERROR(H16/G16,0) -> 0 | J16: =IFERROR(E16*H16,0) -> 0 | K16: =IFERROR(J16/G16,0) -> 0 | L16: =IF(B16="","",IF(J16=MAX(SUMIFS($J$2:$J$200,$B$2:$B$200,B16,$C$2:$C$200,C16,$D$2:$D$200,"A"),SUMIFS($J$2:$J$200,$B$2:$B$200,B16,$C$2:$C$200,C16,$D$2:$D$200,"B")),"Current Winner",""))
I17: =IFERROR(H17/G17,0) -> 0 | J17: =IFERROR(E17*H17,0) -> 0 | K17: =IFERROR(J17/G17,0) -> 0 | L17: =IF(B17="","",IF(J17=MAX(SUMIFS($J$2:$J$200,$B$2:$B$200,B17,$C$2:$C$200,C17,$D$2:$D$200,"A"),SUMIFS($J$2:$J$200,$B$2:$B$200,B17,$C$2:$C$200,C17,$D$2:$D$200,"B")),"Current Winner",""))
I18: =IFERROR(H18/G18,0) -> 0 | J18: =IFERROR(E18*H18,0) -> 0 | K18: =IFERROR(J18/G18,0) -> 0 | L18: =IF(B18="","",IF(J18=MAX(SUMIFS($J$2:$J$200,$B$2:$B$200,B18,$C$2:$C$200,C18,$D$2:$D$200,"A"),SUMIFS($J$2:$J$200,$B$2:$B$200,B18,$C$2:$C$200,C18,$D$2:$D$200,"B")),"Current Winner",""))
I19: =IFERROR(H19/G19,0) -> 0 | J19: =IFERROR(E19*H19,0) -> 0 | K19: =IFERROR(J19/G19,0) -> 0 | L19: =IF(B19="","",IF(J19=MAX(SUMIFS($J$2:$J$200,$B$2:$B$200,B19,$C$2:$C$200,C19,$D$2:$D$200,"A"),SUMIFS($J$2:$J$200,$B$2:$B$200,B19,$C$2:$C$200,C19,$D$2:$D$200,"B")),"Current Winner",""))
I20: =IFERROR(H20/G20,0) -> 0 | J20: =IFERROR(E20*H20,0) -> 0 | K20: =IFERROR(J20/G20,0) -> 0 | L20: =IF(B20="","",IF(J20=MAX(SUMIFS($J$2:$J$200,$B$2:$B$200,B20,$C$2:$C$200,C20,$D$2:$D$200,"A"),SUMIFS($J$2:$J$200,$B$2:$B$200,B20,$C$2:$C$200,C20,$D$2:$D$200,"B")),"Current Winner",""))
I21: =IFERROR(H21/G21,0) -> 0 | J21: =IFERROR(E21*H21,0) -> 0 | K21: =IFERROR(J21/G21,0) -> 0 | L21: =IF(B21="","",IF(J21=MAX(SUMIFS($J$2:$J$200,$B$2:$B$200,B21,$C$2:$C$200,C21,$D$2:$D$200,"A"),SUMIFS($J$2:$J$200,$B$2:$B$200,B21,$C$2:$C$200,C21,$D$2:$D$200,"B")),"Current Winner",""))
... I200: =IFERROR(H200/G200,0) -> 0 | J200: =IFERROR(E200*H200,0) -> 0 | K200: =IFERROR(J200/G200,0) -> 0 | L200: =IF(B200="","",IF(J200=MAX(SUMIFS($J$2:$J$200,$B$2:$B$200,B200,$C$2:$C$200,C200,$D$2:$D$200,"A"),SUMIFS($J$2:$J$200,$B$2:$B$200,B200,$C$2:$C$200,C200,$D$2:$D$200,"B")),"Current Winner",""))

Sheet AB_Dashboard
A1: A/B Price Testing Dashboard
A3: Total Impressions | B3: =SUM(AB_TEST!G2:G200) -> 11100 | D3: How to use
A4: Total Purchases | B4: =SUM(AB_TEST!H2:H200) -> 519 | D4: 1) Add weekly price tests in AB_TEST.
A5: Total Revenue | B5: =SUM(AB_TEST!J2:J200) -> 17327.8 | D5: 2) Keep each test country/app split clean: A vs B.
A6: Avg Conversion | B6: =IFERROR(SUM(AB_TEST!H2:H200)/SUM(AB_TEST!G2:G200),0) -> 0.046756757 | D6: 3) Judge by Revenue first, then Conversion.
A7: Avg ARPU | B7: =IFERROR(SUM(AB_TEST!J2:J200)/SUM(AB_TEST!G2:G200),0) -> 1.5610631 | D7: 4) Run each variant at least 7 days if possible.
A8: Best Variant by Revenue | B8: =INDEX(A13:A14,MATCH(MAX(E13:E14),E13:E14,0)) -> B | D8: 5) After winner is clear, update Play Store pricing.
A10: Variant Summary
A12: Variant | B12: Impressions | C12: Purchases | D12: Conversion | E12: Revenue | F12: ARPU | G12: Revenue Share | H12: Decision
A13: A | B13: =SUMIFS(AB_TEST!G2:G200,AB_TEST!D2:D200,A13) -> 5260 | C13: =SUMIFS(AB_TEST!H2:H200,AB_TEST!D2:D200,A13) -> 196 | D13: =IFERROR(C13/B13,0) -> 0.037262357 | E13: =SUMIFS(AB_TEST!J2:J200,AB_TEST!D2:D200,A13) -> 8282 | F13: =IFERROR(E13/B13,0) -> 1.5745247 | G13: =IFERROR(E13/SUM($E$13:$E$14),0) -> 0.47796027 | H13: =IF(E13=MAX($E$13:$E$14),"Winner","")
A14: B | B14: =SUMIFS(AB_TEST!G2:G200,AB_TEST!D2:D200,A14) -> 5840 | C14: =SUMIFS(AB_TEST!H2:H200,AB_TEST!D2:D200,A14) -> 323 | D14: =IFERROR(C14/B14,0) -> 0.055308219 | E14: =SUMIFS(AB_TEST!J2:J200,AB_TEST!D2:D200,A14) -> 9045.8 | F14: =IFERROR(E14/B14,0) -> 1.5489384 | G14: =IFERROR(E14/SUM($E$13:$E$14),0) -> 0.52203973 | H14: =IF(E14=MAX($E$13:$E$14),"Winner","") -> Winner
A17: Country / App Breakdown
A19: App | B19: Country | C19: Variant | D19: Impressions | E19: Purchases | F19: Conversion | G19: Revenue | H19: ARPU
A20: BLE Scanner | B20: TR | C20: A | D20: =SUMIFS(AB_TEST!G2:G200,AB_TEST!B2:B200,A20,AB_TEST!C2:C200,B20,AB_TEST!D2:D200,C20) -> 1200 | E20: =SUMIFS(AB_TEST!H2:H200,AB_TEST!B2:B200,A20,AB_TEST!C2:C200,B20,AB_TEST!D2:D200,C20) -> 48 | F20: =IFERROR(E20/D20,0) -> 0.04 | G20: =SUMIFS(AB_TEST!J2:J200,AB_TEST!B2:B200,A20,AB_TEST!C2:C200,B20,AB_TEST!D2:D200,C20) -> 1872 | H20: =IFERROR(G20/D20,0) -> 1.56
A21: BLE Scanner | B21: TR | C21: B | D21: =SUMIFS(AB_TEST!G2:G200,AB_TEST!B2:B200,A21,AB_TEST!C2:C200,B21,AB_TEST!D2:D200,C21) -> 1350 | E21: =SUMIFS(AB_TEST!H2:H200,AB_TEST!B2:B200,A21,AB_TEST!C2:C200,B21,AB_TEST!D2:D200,C21) -> 78 | F21: =IFERROR(E21/D21,0) -> 0.057777778 | G21: =SUMIFS(AB_TEST!J2:J200,AB_TEST!B2:B200,A21,AB_TEST!C2:C200,B21,AB_TEST!D2:D200,C21) -> 2262 | H21: =IFERROR(G21/D21,0) -> 1.6755556
A22: Secure Vault | B22: TR | C22: A | D22: =SUMIFS(AB_TEST!G2:G200,AB_TEST!B2:B200,A22,AB_TEST!C2:C200,B22,AB_TEST!D2:D200,C22) -> 900 | E22: =SUMIFS(AB_TEST!H2:H200,AB_TEST!B2:B200,A22,AB_TEST!C2:C200,B22,AB_TEST!D2:D200,C22) -> 32 | F22: =IFERROR(E22/D22,0) -> 0.035555556 | G22: =SUMIFS(AB_TEST!J2:J200,AB_TEST!B2:B200,A22,AB_TEST!C2:C200,B22,AB_TEST!D2:D200,C22) -> 1568 | H22: =IFERROR(G22/D22,0) -> 1.7422222
A23: Secure Vault | B23: TR | C23: B | D23: =SUMIFS(AB_TEST!G2:G200,AB_TEST!B2:B200,A23,AB_TEST!C2:C200,B23,AB_TEST!D2:D200,C23) -> 960 | E23: =SUMIFS(AB_TEST!H2:H200,AB_TEST!B2:B200,A23,AB_TEST!C2:C200,B23,AB_TEST!D2:D200,C23) -> 45 | F23: =IFERROR(E23/D23,0) -> 0.046875 | G23: =SUMIFS(AB_TEST!J2:J200,AB_TEST!B2:B200,A23,AB_TEST!C2:C200,B23,AB_TEST!D2:D200,C23) -> 1755 | H23: =IFERROR(G23/D23,0) -> 1.828125
A24: BLE Scanner | B24: IN | C24: A | D24: =SUMIFS(AB_TEST!G2:G200,AB_TEST!B2:B200,A24,AB_TEST!C2:C200,B24,AB_TEST!D2:D200,C24) -> 2400 | E24: =SUMIFS(AB_TEST!H2:H200,AB_TEST!B2:B200,A24,AB_TEST!C2:C200,B24,AB_TEST!D2:D200,C24) -> 96 | F24: =IFERROR(E24/D24,0) -> 0.04 | G24: =SUMIFS(AB_TEST!J2:J200,AB_TEST!B2:B200,A24,AB_TEST!C2:C200,B24,AB_TEST!D2:D200,C24) -> 4704 | H24: =IFERROR(G24/D24,0) -> 1.96
A25: BLE Scanner | B25: IN | C25: B | D25: =SUMIFS(AB_TEST!G2:G200,AB_TEST!B2:B200,A25,AB_TEST!C2:C200,B25,AB_TEST!D2:D200,C25) -> 2700 | E25: =SUMIFS(AB_TEST!H2:H200,AB_TEST!B2:B200,A25,AB_TEST!C2:C200,B25,AB_TEST!D2:D200,C25) -> 168 | F25: =IFERROR(E25/D25,0) -> 0.062222222 | G25: =SUMIFS(AB_TEST!J2:J200,AB_TEST!B2:B200,A25,AB_TEST!C2:C200,B25,AB_TEST!D2:D200,C25) -> 4872 | H25: =IFERROR(G25/D25,0) -> 1.8044444
A26: Secure Vault | B26: BR | C26: A | D26: =SUMIFS(AB_TEST!G2:G200,AB_TEST!B2:B200,A26,AB_TEST!C2:C200,B26,AB_TEST!D2:D200,C26) -> 760 | E26: =SUMIFS(AB_TEST!H2:H200,AB_TEST!B2:B200,A26,AB_TEST!C2:C200,B26,AB_TEST!D2:D200,C26) -> 20 | F26: =IFERROR(E26/D26,0) -> 0.026315789 | G26: =SUMIFS(AB_TEST!J2:J200,AB_TEST!B2:B200,A26,AB_TEST!C2:C200,B26,AB_TEST!D2:D200,C26) -> 138 | H26: =IFERROR(G26/D26,0) -> 0.18157895
A27: Secure Vault | B27: BR | C27: B | D27: =SUMIFS(AB_TEST!G2:G200,AB_TEST!B2:B200,A27,AB_TEST!C2:C200,B27,AB_TEST!D2:D200,C27) -> 830 | E27: =SUMIFS(AB_TEST!H2:H200,AB_TEST!B2:B200,A27,AB_TEST!C2:C200,B27,AB_TEST!D2:D200,C27) -> 32 | F27: =IFERROR(E27/D27,0) -> 0.038554217 | G27: =SUMIFS(AB_TEST!J2:J200,AB_TEST!B2:B200,A27,AB_TEST!C2:C200,B27,AB_TEST!D2:D200,C27) -> 156.8 | H27: =IFERROR(G27/D27,0) -> 0.18891566

Sheet AB_Setup
A1: AB Price Testing Setup
A2: Editable fields | B2: Meaning | C2: Example | D2: Notes
A3: App | B3: Which app / SKU you are testing | C3: BLE Scanner | D3: Use same naming in AB_TEST
A4: Country | B4: Play Store country code | C4: TR | D4: TR, US, IN, BR etc.
A5: Variant | B5: Price variant label | C5: A / B | D5: A = higher price, B = lower price recommended
A6: Impressions | B6: Paywall / purchase screen views | C6: 1000 | D6: Use Play Console / analytics
A7: Purchases | B7: Completed purchases | C7: 50 | D7: Use Play Console order data
A8: Revenue | B8: Auto calculated | D8: Price × Purchases
A9: Conversion | B9: Auto calculated | D9: Purchases ÷ Impressions
A10: Decision metric | B10: Primary winner metric | C10: Revenue | D10: Conversion alone is not enough
