Workbook

Sheet Dashboard
A1: Play Store PPP Pricing Template
A3: Base Price USD | B3: 1
A4: Global Min USD | B4: 0.49
A5: High PPP Floor USD | B5: 1.99
A6: Default Market Adj | B6: 1
A7: Default FX Source | B7: Manual / Google Sheets formula
A8: Last Updated | B8: 2026-05-01
A9: Notes | B9: Edit yellow cells only. Final price uses PPP + Market Adj + FX + rounding rules.
A10: Output Sheet | B10: PricingModel
A12: How to use | B12: 1) Set Base Price USD in B3 | C12: 2) Edit PPP/Market Adj/FX in PricingModel | D12: 3) Check Final Rounded Local Price | E12: 4) Enter prices manually in Play Console
A14: Tier | B14: PPP Range | C14: Strategy | D14: Typical Use
A15: A | B15: 0.80 - 1.00 | C15: Premium / near full price | D15: US, wealthier EU
A16: B | B16: 0.60 - 0.79 | C16: Slight discount | D16: Strong purchasing power
A17: C | B17: 0.40 - 0.59 | C17: Mid discount | D17: Balanced conversion/revenue
A18: D/E | B18: 0.10 - 0.39 | C18: Aggressive local price | D18: Volume markets

Sheet PricingModel
A1: 1. sütun | B1: Country | C1: Country Code | D1: Currency | E1: PPP Factor | F1: Tier | G1: Base USD | H1: PPP Price USD | I1: Market Adj | J1: FX USD→Local | K1: Raw Local Price | L1: Rounding Group | M1: Final Rounded Local | N1: Final USD Approx | O1: Recommended Action | P1: FX Formula for Google Sheets | Q1: Notes
A2: Arnavutluk | B2: Albania | C2: AL | D2: ALL | E2: 0.35 | F2: D | G2: =Dashboard!$B$3 -> 1 | H2: =MAX(Dashboard!$B$4,G2*E2) -> 0.49 | I2: 1 | J2: =IFERROR(__xludf.DUMMYFUNCTION("GOOGLEFINANCE(""CURRENCY:USDALL"")"),81.26480000000001) -> 81.2648 | K2: =H2*I2*J2 -> 39.819752 | L2: TRY_TIERS | M2: =IF(L2="TRY_TIERS",IF(K2<25,19,IF(K2<35,29,IF(K2<45,39,IF(K2<60,49,79)))), IF(L2="INR_TIERS",IF(K2<40,29,IF(K2<70,49,99)), IF(L2="BRL_90",IF(K2<3,2.9,IF(K2<6,4.9,IF(K2<10,6.9,9.9))), IF(L2="IDR_000",ROUND(K2/1000,0)*1000, IF(L2="JPY_00",ROUND(K2/100,0)*100, IF(L2="KRW_000",ROUND(K2/1000,0)*1000, IF(L2="VND_000",ROUND(K2/1000,0)*1000, IF(OR(L2="USD_99",L2="EUR_99",L2="GBP_99",L2="CAD_99",L2="AUD_99",L2="PLN_99"),MAX(0.49,ROUND(K2,0)-0.01), IF(L2="MXN_00",ROUND(K2,0),IF(L2="THB_00",ROUND(K2,0),ROUND(K2,2))))))))))) -> 39 | N2: =M2/J2 -> 0.47991258 | P2: =IFERROR(__xludf.DUMMYFUNCTION("GOOGLEFINANCE(""CURRENCY:USDALL"")"),81.26480000000001) -> 81.2648
A3: Cezayir | B3: Algeria | C3: DZ | D3: DZD | E3: 0.28 | F3: D | G3: =Dashboard!$B$3 -> 1 | H3: =MAX(Dashboard!$B$4,G3*E3) -> 0.49 | I3: 1 | J3: =IFERROR(__xludf.DUMMYFUNCTION("GOOGLEFINANCE(""CURRENCY:USDDZD"")"),132.3826) -> 132.3826 | K3: =H3*I3*J3 -> 64.867474 | L3: TRY_TIERS | M3: =IF(L3="TRY_TIERS",IF(K3<25,19,IF(K3<35,29,IF(K3<45,39,IF(K3<60,49,79)))), IF(L3="INR_TIERS",IF(K3<40,29,IF(K3<70,49,99)), IF(L3="BRL_90",IF(K3<3,2.9,IF(K3<6,4.9,IF(K3<10,6.9,9.9))), IF(L3="IDR_000",ROUND(K3/1000,0)*1000, IF(L3="JPY_00",ROUND(K3/100,0)*100, IF(L3="KRW_000",ROUND(K3/1000,0)*1000, IF(L3="VND_000",ROUND(K3/1000,0)*1000, IF(OR(L3="USD_99",L3="EUR_99",L3="GBP_99",L3="CAD_99",L3="AUD_99",L3="PLN_99"),MAX(0.49,ROUND(K3,0)-0.01), IF(L3="MXN_00",ROUND(K3,0),IF(L3="THB_00",ROUND(K3,0),ROUND(K3,2))))))))))) -> 79 | N3: =M3/J3 -> 0.59675516 | P3: =IFERROR(__xludf.DUMMYFUNCTION("GOOGLEFINANCE(""CURRENCY:USDDZD"")"),132.3826) -> 132.3826
A4: Angola | B4: Angola | C4: AO | D4: AOA | E4: 0.22 | F4: E | G4: =Dashboard!$B$3 -> 1 | H4: =MAX(Dashboard!$B$4,G4*E4) -> 0.49 | I4: 1 | J4: =IFERROR(__xludf.DUMMYFUNCTION("GOOGLEFINANCE(""CURRENCY:USDAOA"")"),918.0) -> 918 | K4: =H4*I4*J4 -> 449.82 | L4: THB_00 | M4: =IF(L4="TRY_TIERS",IF(K4<25,19,IF(K4<35,29,IF(K4<45,39,IF(K4<60,49,79)))), IF(L4="INR_TIERS",IF(K4<40,29,IF(K4<70,49,99)), IF(L4="BRL_90",IF(K4<3,2.9,IF(K4<6,4.9,IF(K4<10,6.9,9.9))), IF(L4="IDR_000",ROUND(K4/1000,0)*1000, IF(L4="JPY_00",ROUND(K4/100,0)*100, IF(L4="KRW_000",ROUND(K4/1000,0)*1000, IF(L4="VND_000",ROUND(K4/1000,0)*1000, IF(OR(L4="USD_99",L4="EUR_99",L4="GBP_99",L4="CAD_99",L4="AUD_99",L4="PLN_99"),MAX(0.49,ROUND(K4,0)-0.01), IF(L4="MXN_00",ROUND(K4,0),IF(L4="THB_00",ROUND(K4,0),ROUND(K4,2))))))))))) -> 450 | N4: =M4/J4 -> 0.49019608 | P4: =IFERROR(__xludf.DUMMYFUNCTION("GOOGLEFINANCE(""CURRENCY:USDAOA"")"),918.0) -> 918
A5: Antigua ve Barbuda | B5: Antigua and Barbuda | C5: AG | D5: XCD | E5: 0.65 | F5: B | G5: =Dashboard!$B$3 -> 1 | H5: =MAX(Dashboard!$B$4,G5*E5) -> 0.65 | I5: 1 | J5: =IFERROR(__xludf.DUMMYFUNCTION("GOOGLEFINANCE(""CURRENCY:USDXCD"")"),2.70255) -> 2.70255 | K5: =H5*I5*J5 -> 1.7566575 | L5: USD_99 | M5: =IF(L5="TRY_TIERS",IF(K5<25,19,IF(K5<35,29,IF(K5<45,39,IF(K5<60,49,79)))), IF(L5="INR_TIERS",IF(K5<40,29,IF(K5<70,49,99)), IF(L5="BRL_90",IF(K5<3,2.9,IF(K5<6,4.9,IF(K5<10,6.9,9.9))), IF(L5="IDR_000",ROUND(K5/1000,0)*1000, IF(L5="JPY_00",ROUND(K5/100,0)*100, IF(L5="KRW_000",ROUND(K5/1000,0)*1000, IF(L5="VND_000",ROUND(K5/1000,0)*1000, IF(OR(L5="USD_99",L5="EUR_99",L5="GBP_99",L5="CAD_99",L5="AUD_99",L5="PLN_99"),MAX(0.49,ROUND(K5,0)-0.01), IF(L5="MXN_00",ROUND(K5,0),IF(L5="THB_00",ROUND(K5,0),ROUND(K5,2))))))))))) -> 1.99 | N5: =M5/J5 -> 0.7363416 | P5: =IFERROR(__xludf.DUMMYFUNCTION("GOOGLEFINANCE(""CURRENCY:USDXCD"")"),2.70255) -> 2.70255
A6: Arjantin | B6: Argentina | C6: AR | D6: ARS | E6: 0.3 | F6: D | G6: =Dashboard!$B$3 -> 1 | H6: =MAX(Dashboard!$B$4,G6*E6) -> 0.49 | I6: 1 | J6: =IFERROR(__xludf.DUMMYFUNCTION("GOOGLEFINANCE(""CURRENCY:USDARS"")"),1385.0) -> 1385 | K6: =H6*I6*J6 -> 678.65 | L6: THB_00 | M6: =IF(L6="TRY_TIERS",IF(K6<25,19,IF(K6<35,29,IF(K6<45,39,IF(K6<60,49,79)))), IF(L6="INR_TIERS",IF(K6<40,29,IF(K6<70,49,99)), IF(L6="BRL_90",IF(K6<3,2.9,IF(K6<6,4.9,IF(K6<10,6.9,9.9))), IF(L6="IDR_000",ROUND(K6/1000,0)*1000, IF(L6="JPY_00",ROUND(K6/100,0)*100, IF(L6="KRW_000",ROUND(K6/1000,0)*1000, IF(L6="VND_000",ROUND(K6/1000,0)*1000, IF(OR(L6="USD_99",L6="EUR_99",L6="GBP_99",L6="CAD_99",L6="AUD_99",L6="PLN_99"),MAX(0.49,ROUND(K6,0)-0.01), IF(L6="MXN_00",ROUND(K6,0),IF(L6="THB_00",ROUND(K6,0),ROUND(K6,2))))))))))) -> 679 | N6: =M6/J6 -> 0.49025271 | P6: =IFERROR(__xludf.DUMMYFUNCTION("GOOGLEFINANCE(""CURRENCY:USDARS"")"),1385.0) -> 1385
A7: Ermenistan | B7: Armenia | C7: AM | D7: AMD | E7: 0.3 | F7: D | G7: =Dashboard!$B$3 -> 1 | H7: =MAX(Dashboard!$B$4,G7*E7) -> 0.49 | I7: 1 | J7: =IFERROR(__xludf.DUMMYFUNCTION("GOOGLEFINANCE(""CURRENCY:USDAMD"")"),368.0783) -> 368.0783 | K7: =H7*I7*J7 -> 180.35837 | L7: USD_99 | M7: =IF(L7="TRY_TIERS",IF(K7<25,19,IF(K7<35,29,IF(K7<45,39,IF(K7<60,49,79)))), IF(L7="INR_TIERS",IF(K7<40,29,IF(K7<70,49,99)), IF(L7="BRL_90",IF(K7<3,2.9,IF(K7<6,4.9,IF(K7<10,6.9,9.9))), IF(L7="IDR_000",ROUND(K7/1000,0)*1000, IF(L7="JPY_00",ROUND(K7/100,0)*100, IF(L7="KRW_000",ROUND(K7/1000,0)*1000, IF(L7="VND_000",ROUND(K7/1000,0)*1000, IF(OR(L7="USD_99",L7="EUR_99",L7="GBP_99",L7="CAD_99",L7="AUD_99",L7="PLN_99"),MAX(0.49,ROUND(K7,0)-0.01), IF(L7="MXN_00",ROUND(K7,0),IF(L7="THB_00",ROUND(K7,0),ROUND(K7,2))))))))))) -> 179.99 | N7: =M7/J7 -> 0.48899922 | P7: =IFERROR(__xludf.DUMMYFUNCTION("GOOGLEFINANCE(""CURRENCY:USDAMD"")"),368.0783) -> 368.0783
A8: Aruba | B8: Aruba | C8: AW | D8: AWG | E8: 0.75 | F8: B | G8: =Dashboard!$B$3 -> 1 | H8: =MAX(Dashboard!$B$4,G8*E8) -> 0.75 | I8: 1 | J8: =IFERROR(__xludf.DUMMYFUNCTION("GOOGLEFINANCE(""CURRENCY:USDAWG"")"),1.8025) -> 1.8025 | K8: =H8*I8*J8 -> 1.351875 | L8: PLN_99 | M8: =IF(L8="TRY_TIERS",IF(K8<25,19,IF(K8<35,29,IF(K8<45,39,IF(K8<60,49,79)))), IF(L8="INR_TIERS",IF(K8<40,29,IF(K8<70,49,99)), IF(L8="BRL_90",IF(K8<3,2.9,IF(K8<6,4.9,IF(K8<10,6.9,9.9))), IF(L8="IDR_000",ROUND(K8/1000,0)*1000, IF(L8="JPY_00",ROUND(K8/100,0)*100, IF(L8="KRW_000",ROUND(K8/1000,0)*1000, IF(L8="VND_000",ROUND(K8/1000,0)*1000, IF(OR(L8="USD_99",L8="EUR_99",L8="GBP_99",L8="CAD_99",L8="AUD_99",L8="PLN_99"),MAX(0.49,ROUND(K8,0)-0.01), IF(L8="MXN_00",ROUND(K8,0),IF(L8="THB_00",ROUND(K8,0),ROUND(K8,2))))))))))) -> 0.99 | N8: =M8/J8 -> 0.54923717 | P8: =IFERROR(__xludf.DUMMYFUNCTION("GOOGLEFINANCE(""CURRENCY:USDAWG"")"),1.8025) -> 1.8025
A9: Avustralya | B9: Australia | C9: AU | D9: AUD | E9: 0.82 | F9: =IF(E9>=0.8,"A",IF(E9>=0.6,"B",IF(E9>=0.4,"C",IF(E9>=0.2,"D","E")))) -> A | G9: =Dashboard!$B$3 -> 1 | H9: =MAX(Dashboard!$B$4,G9*E9) -> 0.82 | I9: 1 | J9: =IFERROR(__xludf.DUMMYFUNCTION("GOOGLEFINANCE(""CURRENCY:USDAUD"")"),1.381082) -> 1.381082 | K9: =H9*I9*J9 -> 1.1324872 | L9: AUD_99 | M9: =IF(L9="TRY_TIERS",IF(K9<25,19,IF(K9<35,29,IF(K9<45,39,IF(K9<60,49,79)))), IF(L9="INR_TIERS",IF(K9<40,29,IF(K9<70,49,99)), IF(L9="BRL_90",IF(K9<3,2.9,IF(K9<6,4.9,IF(K9<10,6.9,9.9))), IF(L9="IDR_000",ROUND(K9/1000,0)*1000, IF(L9="JPY_00",ROUND(K9/100,0)*100, IF(L9="KRW_000",ROUND(K9/1000,0)*1000, IF(L9="VND_000",ROUND(K9/1000,0)*1000, IF(OR(L9="USD_99",L9="EUR_99",L9="GBP_99",L9="CAD_99",L9="AUD_99",L9="PLN_99"),MAX(0.49,ROUND(K9,0)-0.01), IF(L9="MXN_00",ROUND(K9,0),IF(L9="THB_00",ROUND(K9,0),ROUND(K9,2))))))))))) -> 0.99 | N9: =M9/J9 -> 0.71682927 | O9: =IF(N9<Dashboard!$B$4,"Below global min",IF(AND(E9>=0.8,N9<Dashboard!$B$5),"Raise high-PPP floor","OK")) -> Raise high-PPP floor | P9: =IFERROR(__xludf.DUMMYFUNCTION("GOOGLEFINANCE(""CURRENCY:USDAUD"")"),1.381082) -> 1.381082
A10: Avusturya | B10: Austria | C10: AT | D10: EUR | E10: 0.86 | F10: A | G10: =Dashboard!$B$3 -> 1 | H10: =MAX(Dashboard!$B$4,G10*E10) -> 0.86 | I10: 1 | J10: =IFERROR(__xludf.DUMMYFUNCTION("GOOGLEFINANCE(""CURRENCY:USDEUR"")"),0.8519) -> 0.8519 | K10: =H10*I10*J10 -> 0.732634 | M10: =IF(L10="TRY_TIERS",IF(K10<25,19,IF(K10<35,29,IF(K10<45,39,IF(K10<60,49,79)))), IF(L10="INR_TIERS",IF(K10<40,29,IF(K10<70,49,99)), IF(L10="BRL_90",IF(K10<3,2.9,IF(K10<6,4.9,IF(K10<10,6.9,9.9))), IF(L10="IDR_000",ROUND(K10/1000,0)*1000, IF(L10="JPY_00",ROUND(K10/100,0)*100, IF(L10="KRW_000",ROUND(K10/1000,0)*1000, IF(L10="VND_000",ROUND(K10/1000,0)*1000, IF(OR(L10="USD_99",L10="EUR_99",L10="GBP_99",L10="CAD_99",L10="AUD_99",L10="PLN_99"),MAX(0.49,ROUND(K10,0)-0.01), IF(L10="MXN_00",ROUND(K10,0),IF(L10="THB_00",ROUND(K10,0),ROUND(K10,2))))))))))) -> 0.73 | N10: =M10/J10 -> 0.85690809 | P10: =IFERROR(__xludf.DUMMYFUNCTION("GOOGLEFINANCE(""CURRENCY:USDEUR"")"),0.8519) -> 0.8519
A11: Azerbaycan | B11: Azerbaijan | C11: AZ | D11: AZN | E11: 0.4 | F11: D | G11: =Dashboard!$B$3 -> 1 | H11: =MAX(Dashboard!$B$4,G11*E11) -> 0.49 | I11: 1 | J11: =IFERROR(__xludf.DUMMYFUNCTION("GOOGLEFINANCE(""CURRENCY:USDAZN"")"),1.7) -> 1.7 | K11: =H11*I11*J11 -> 0.833 | M11: =IF(L11="TRY_TIERS",IF(K11<25,19,IF(K11<35,29,IF(K11<45,39,IF(K11<60,49,79)))), IF(L11="INR_TIERS",IF(K11<40,29,IF(K11<70,49,99)), IF(L11="BRL_90",IF(K11<3,2.9,IF(K11<6,4.9,IF(K11<10,6.9,9.9))), IF(L11="IDR_000",ROUND(K11/1000,0)*1000, IF(L11="JPY_00",ROUND(K11/100,0)*100, IF(L11="KRW_000",ROUND(K11/1000,0)*1000, IF(L11="VND_000",ROUND(K11/1000,0)*1000, IF(OR(L11="USD_99",L11="EUR_99",L11="GBP_99",L11="CAD_99",L11="AUD_99",L11="PLN_99"),MAX(0.49,ROUND(K11,0)-0.01), IF(L11="MXN_00",ROUND(K11,0),IF(L11="THB_00",ROUND(K11,0),ROUND(K11,2))))))))))) -> 0.83 | N11: =M11/J11 -> 0.48823529 | P11: =IFERROR(__xludf.DUMMYFUNCTION("GOOGLEFINANCE(""CURRENCY:USDAZN"")"),1.7) -> 1.7
A12: Bahamalar | B12: Bahamas | C12: BS | D12: BSD | E12: 0.75 | F12: B | G12: =Dashboard!$B$3 -> 1 | H12: =MAX(Dashboard!$B$4,G12*E12) -> 0.75 | I12: 1 | J12: =IFERROR(__xludf.DUMMYFUNCTION("GOOGLEFINANCE(""CURRENCY:USDBSD"")"),1.000136) -> 1.000136 | K12: =H12*I12*J12 -> 0.750102 | M12: =IF(L12="TRY_TIERS",IF(K12<25,19,IF(K12<35,29,IF(K12<45,39,IF(K12<60,49,79)))), IF(L12="INR_TIERS",IF(K12<40,29,IF(K12<70,49,99)), IF(L12="BRL_90",IF(K12<3,2.9,IF(K12<6,4.9,IF(K12<10,6.9,9.9))), IF(L12="IDR_000",ROUND(K12/1000,0)*1000, IF(L12="JPY_00",ROUND(K12/100,0)*100, IF(L12="KRW_000",ROUND(K12/1000,0)*1000, IF(L12="VND_000",ROUND(K12/1000,0)*1000, IF(OR(L12="USD_99",L12="EUR_99",L12="GBP_99",L12="CAD_99",L12="AUD_99",L12="PLN_99"),MAX(0.49,ROUND(K12,0)-0.01), IF(L12="MXN_00",ROUND(K12,0),IF(L12="THB_00",ROUND(K12,0),ROUND(K12,2))))))))))) -> 0.75 | N12: =M12/J12 -> 0.74989801 | P12: =IFERROR(__xludf.DUMMYFUNCTION("GOOGLEFINANCE(""CURRENCY:USDBSD"")"),1.000136) -> 1.000136
A13: Bahreyn | B13: Bahrain | C13: BH | D13: BHD | E13: 0.85 | F13: A | G13: =Dashboard!$B$3 -> 1 | H13: =MAX(Dashboard!$B$4,G13*E13) -> 0.85 | I13: 1 | J13: =IFERROR(__xludf.DUMMYFUNCTION("GOOGLEFINANCE(""CURRENCY:USDBHD"")"),0.3774469) -> 0.3774469 | K13: =H13*I13*J13 -> 0.32082986 | M13: =IF(L13="TRY_TIERS",IF(K13<25,19,IF(K13<35,29,IF(K13<45,39,IF(K13<60,49,79)))), IF(L13="INR_TIERS",IF(K13<40,29,IF(K13<70,49,99)), IF(L13="BRL_90",IF(K13<3,2.9,IF(K13<6,4.9,IF(K13<10,6.9,9.9))), IF(L13="IDR_000",ROUND(K13/1000,0)*1000, IF(L13="JPY_00",ROUND(K13/100,0)*100, IF(L13="KRW_000",ROUND(K13/1000,0)*1000, IF(L13="VND_000",ROUND(K13/1000,0)*1000, IF(OR(L13="USD_99",L13="EUR_99",L13="GBP_99",L13="CAD_99",L13="AUD_99",L13="PLN_99"),MAX(0.49,ROUND(K13,0)-0.01), IF(L13="MXN_00",ROUND(K13,0),IF(L13="THB_00",ROUND(K13,0),ROUND(K13,2))))))))))) -> 0.32 | N13: =M13/J13 -> 0.84780137 | P13: =IFERROR(__xludf.DUMMYFUNCTION("GOOGLEFINANCE(""CURRENCY:USDBHD"")"),0.3774469) -> 0.3774469
A14: Bangladeş | B14: Bangladesh | C14: BD | D14: BDT | E14: 0.15 | F14: E | G14: =Dashboard!$B$3 -> 1 | H14: =MAX(Dashboard!$B$4,G14*E14) -> 0.49 | I14: 1 | J14: =IFERROR(__xludf.DUMMYFUNCTION("GOOGLEFINANCE(""CURRENCY:USDBDT"")"),122.9364) -> 122.9364 | K14: =H14*I14*J14 -> 60.238836 | M14: =IF(L14="TRY_TIERS",IF(K14<25,19,IF(K14<35,29,IF(K14<45,39,IF(K14<60,49,79)))), IF(L14="INR_TIERS",IF(K14<40,29,IF(K14<70,49,99)), IF(L14="BRL_90",IF(K14<3,2.9,IF(K14<6,4.9,IF(K14<10,6.9,9.9))), IF(L14="IDR_000",ROUND(K14/1000,0)*1000, IF(L14="JPY_00",ROUND(K14/100,0)*100, IF(L14="KRW_000",ROUND(K14/1000,0)*1000, IF(L14="VND_000",ROUND(K14/1000,0)*1000, IF(OR(L14="USD_99",L14="EUR_99",L14="GBP_99",L14="CAD_99",L14="AUD_99",L14="PLN_99"),MAX(0.49,ROUND(K14,0)-0.01), IF(L14="MXN_00",ROUND(K14,0),IF(L14="THB_00",ROUND(K14,0),ROUND(K14,2))))))))))) -> 60.24 | N14: =M14/J14 -> 0.49000947 | P14: =IFERROR(__xludf.DUMMYFUNCTION("GOOGLEFINANCE(""CURRENCY:USDBDT"")"),122.9364) -> 122.9364
A15: Belarus | B15: Belarus | C15: BY | D15: BYN | E15: 0.4 | F15: D | G15: =Dashboard!$B$3 -> 1 | H15: =MAX(Dashboard!$B$4,G15*E15) -> 0.49 | I15: 1 | J15: =IFERROR(__xludf.DUMMYFUNCTION("GOOGLEFINANCE(""CURRENCY:USDBYN"")"),2.7962249999999997) -> 2.796225 | K15: =H15*I15*J15 -> 1.3701503 | M15: =IF(L15="TRY_TIERS",IF(K15<25,19,IF(K15<35,29,IF(K15<45,39,IF(K15<60,49,79)))), IF(L15="INR_TIERS",IF(K15<40,29,IF(K15<70,49,99)), IF(L15="BRL_90",IF(K15<3,2.9,IF(K15<6,4.9,IF(K15<10,6.9,9.9))), IF(L15="IDR_000",ROUND(K15/1000,0)*1000, IF(L15="JPY_00",ROUND(K15/100,0)*100, IF(L15="KRW_000",ROUND(K15/1000,0)*1000, IF(L15="VND_000",ROUND(K15/1000,0)*1000, IF(OR(L15="USD_99",L15="EUR_99",L15="GBP_99",L15="CAD_99",L15="AUD_99",L15="PLN_99"),MAX(0.49,ROUND(K15,0)-0.01), IF(L15="MXN_00",ROUND(K15,0),IF(L15="THB_00",ROUND(K15,0),ROUND(K15,2))))))))))) -> 1.37 | N15: =M15/J15 -> 0.48994627 | P15: =IFERROR(__xludf.DUMMYFUNCTION("GOOGLEFINANCE(""CURRENCY:USDBYN"")"),2.7962249999999997) -> 2.796225
A16: Belçika | B16: Belgium | C16: BE | D16: EUR | E16: 0.84 | F16: A | G16: =Dashboard!$B$3 -> 1 | H16: =MAX(Dashboard!$B$4,G16*E16) -> 0.84 | I16: 1 | J16: =IFERROR(__xludf.DUMMYFUNCTION("GOOGLEFINANCE(""CURRENCY:USDEUR"")"),0.8519) -> 0.8519 | K16: =H16*I16*J16 -> 0.715596 | M16: =IF(L16="TRY_TIERS",IF(K16<25,19,IF(K16<35,29,IF(K16<45,39,IF(K16<60,49,79)))), IF(L16="INR_TIERS",IF(K16<40,29,IF(K16<70,49,99)), IF(L16="BRL_90",IF(K16<3,2.9,IF(K16<6,4.9,IF(K16<10,6.9,9.9))), IF(L16="IDR_000",ROUND(K16/1000,0)*1000, IF(L16="JPY_00",ROUND(K16/100,0)*100, IF(L16="KRW_000",ROUND(K16/1000,0)*1000, IF(L16="VND_000",ROUND(K16/1000,0)*1000, IF(OR(L16="USD_99",L16="EUR_99",L16="GBP_99",L16="CAD_99",L16="AUD_99",L16="PLN_99"),MAX(0.49,ROUND(K16,0)-0.01), IF(L16="MXN_00",ROUND(K16,0),IF(L16="THB_00",ROUND(K16,0),ROUND(K16,2))))))))))) -> 0.72 | N16: =M16/J16 -> 0.84516962 | P16: =IFERROR(__xludf.DUMMYFUNCTION("GOOGLEFINANCE(""CURRENCY:USDEUR"")"),0.8519) -> 0.8519
A17: Belize | B17: Belize | C17: BZ | D17: BZD | E17: 0.35 | F17: D | G17: =Dashboard!$B$3 -> 1 | H17: =MAX(Dashboard!$B$4,G17*E17) -> 0.49 | I17: 1 | J17: =IFERROR(__xludf.DUMMYFUNCTION("GOOGLEFINANCE(""CURRENCY:USDBZD"")"),2.011432) -> 2.011432 | K17: =H17*I17*J17 -> 0.98560168 | M17: =IF(L17="TRY_TIERS",IF(K17<25,19,IF(K17<35,29,IF(K17<45,39,IF(K17<60,49,79)))), IF(L17="INR_TIERS",IF(K17<40,29,IF(K17<70,49,99)), IF(L17="BRL_90",IF(K17<3,2.9,IF(K17<6,4.9,IF(K17<10,6.9,9.9))), IF(L17="IDR_000",ROUND(K17/1000,0)*1000, IF(L17="JPY_00",ROUND(K17/100,0)*100, IF(L17="KRW_000",ROUND(K17/1000,0)*1000, IF(L17="VND_000",ROUND(K17/1000,0)*1000, IF(OR(L17="USD_99",L17="EUR_99",L17="GBP_99",L17="CAD_99",L17="AUD_99",L17="PLN_99"),MAX(0.49,ROUND(K17,0)-0.01), IF(L17="MXN_00",ROUND(K17,0),IF(L17="THB_00",ROUND(K17,0),ROUND(K17,2))))))))))) -> 0.99 | N17: =M17/J17 -> 0.49218666 | P17: =IFERROR(__xludf.DUMMYFUNCTION("GOOGLEFINANCE(""CURRENCY:USDBZD"")"),2.011432) -> 2.011432
A18: Benin | B18: Benin | C18: BJ | D18: XOF | E18: 0.18 | F18: E | G18: =Dashboard!$B$3 -> 1 | H18: =MAX(Dashboard!$B$4,G18*E18) -> 0.49 | I18: 1 | J18: =IFERROR(__xludf.DUMMYFUNCTION("GOOGLEFINANCE(""CURRENCY:USDXOF"")"),558.7654) -> 558.7654 | K18: =H18*I18*J18 -> 273.79505 | M18: =IF(L18="TRY_TIERS",IF(K18<25,19,IF(K18<35,29,IF(K18<45,39,IF(K18<60,49,79)))), IF(L18="INR_TIERS",IF(K18<40,29,IF(K18<70,49,99)), IF(L18="BRL_90",IF(K18<3,2.9,IF(K18<6,4.9,IF(K18<10,6.9,9.9))), IF(L18="IDR_000",ROUND(K18/1000,0)*1000, IF(L18="JPY_00",ROUND(K18/100,0)*100, IF(L18="KRW_000",ROUND(K18/1000,0)*1000, IF(L18="VND_000",ROUND(K18/1000,0)*1000, IF(OR(L18="USD_99",L18="EUR_99",L18="GBP_99",L18="CAD_99",L18="AUD_99",L18="PLN_99"),MAX(0.49,ROUND(K18,0)-0.01), IF(L18="MXN_00",ROUND(K18,0),IF(L18="THB_00",ROUND(K18,0),ROUND(K18,2))))))))))) -> 273.8 | N18: =M18/J18 -> 0.49000887 | P18: =IFERROR(__xludf.DUMMYFUNCTION("GOOGLEFINANCE(""CURRENCY:USDXOF"")"),558.7654) -> 558.7654
A19: Bermuda | B19: Bermuda | C19: BM | D19: BMD | E19: 1 | F19: A | G19: =Dashboard!$B$3 -> 1 | H19: =MAX(Dashboard!$B$4,G19*E19) -> 1 | I19: 1 | J19: =IFERROR(__xludf.DUMMYFUNCTION("GOOGLEFINANCE(""CURRENCY:USDBMD"")"),1.0) -> 1 | K19: =H19*I19*J19 -> 1 | M19: =IF(L19="TRY_TIERS",IF(K19<25,19,IF(K19<35,29,IF(K19<45,39,IF(K19<60,49,79)))), IF(L19="INR_TIERS",IF(K19<40,29,IF(K19<70,49,99)), IF(L19="BRL_90",IF(K19<3,2.9,IF(K19<6,4.9,IF(K19<10,6.9,9.9))), IF(L19="IDR_000",ROUND(K19/1000,0)*1000, IF(L19="JPY_00",ROUND(K19/100,0)*100, IF(L19="KRW_000",ROUND(K19/1000,0)*1000, IF(L19="VND_000",ROUND(K19/1000,0)*1000, IF(OR(L19="USD_99",L19="EUR_99",L19="GBP_99",L19="CAD_99",L19="AUD_99",L19="PLN_99"),MAX(0.49,ROUND(K19,0)-0.01), IF(L19="MXN_00",ROUND(K19,0),IF(L19="THB_00",ROUND(K19,0),ROUND(K19,2))))))))))) -> 1 | N19: =M19/J19 -> 1 | P19: =IFERROR(__xludf.DUMMYFUNCTION("GOOGLEFINANCE(""CURRENCY:USDBMD"")"),1.0) -> 1
A20: Bolivya | B20: Bolivia | C20: BO | D20: BOB-BOV | E20: 0.3 | F20: D | G20: =Dashboard!$B$3 -> 1 | H20: =MAX(Dashboard!$B$4,G20*E20) -> 0.49 | I20: 1 | J20: =IFERROR(__xludf.DUMMYFUNCTION("GOOGLEFINANCE(""CURRENCY:USDBOB"")"),6.910945) -> 6.910945 | K20: =H20*I20*J20 -> 3.386363 | M20: =IF(L20="TRY_TIERS",IF(K20<25,19,IF(K20<35,29,IF(K20<45,39,IF(K20<60,49,79)))), IF(L20="INR_TIERS",IF(K20<40,29,IF(K20<70,49,99)), IF(L20="BRL_90",IF(K20<3,2.9,IF(K20<6,4.9,IF(K20<10,6.9,9.9))), IF(L20="IDR_000",ROUND(K20/1000,0)*1000, IF(L20="JPY_00",ROUND(K20/100,0)*100, IF(L20="KRW_000",ROUND(K20/1000,0)*1000, IF(L20="VND_000",ROUND(K20/1000,0)*1000, IF(OR(L20="USD_99",L20="EUR_99",L20="GBP_99",L20="CAD_99",L20="AUD_99",L20="PLN_99"),MAX(0.49,ROUND(K20,0)-0.01), IF(L20="MXN_00",ROUND(K20,0),IF(L20="THB_00",ROUND(K20,0),ROUND(K20,2))))))))))) -> 3.39 | N20: =M20/J20 -> 0.49052626 | P20: =IFERROR(__xludf.DUMMYFUNCTION("GOOGLEFINANCE(""CURRENCY:USDBOB"")"),6.910945) -> 6.910945
A21: Bosna-Hersek | B21: Bosnia and Herzegovina | C21: BA | D21: BAM | E21: 0.45 | F21: C | G21: =Dashboard!$B$3 -> 1 | H21: =MAX(Dashboard!$B$4,G21*E21) -> 0.49 | I21: 1 | J21: =IFERROR(__xludf.DUMMYFUNCTION("GOOGLEFINANCE(""CURRENCY:USDBAM"")"),1.6660139999999999) -> 1.666014 | K21: =H21*I21*J21 -> 0.81634686 | M21: =IF(L21="TRY_TIERS",IF(K21<25,19,IF(K21<35,29,IF(K21<45,39,IF(K21<60,49,79)))), IF(L21="INR_TIERS",IF(K21<40,29,IF(K21<70,49,99)), IF(L21="BRL_90",IF(K21<3,2.9,IF(K21<6,4.9,IF(K21<10,6.9,9.9))), IF(L21="IDR_000",ROUND(K21/1000,0)*1000, IF(L21="JPY_00",ROUND(K21/100,0)*100, IF(L21="KRW_000",ROUND(K21/1000,0)*1000, IF(L21="VND_000",ROUND(K21/1000,0)*1000, IF(OR(L21="USD_99",L21="EUR_99",L21="GBP_99",L21="CAD_99",L21="AUD_99",L21="PLN_99"),MAX(0.49,ROUND(K21,0)-0.01), IF(L21="MXN_00",ROUND(K21,0),IF(L21="THB_00",ROUND(K21,0),ROUND(K21,2))))))))))) -> 0.82 | N21: =M21/J21 -> 0.49219274 | P21: =IFERROR(__xludf.DUMMYFUNCTION("GOOGLEFINANCE(""CURRENCY:USDBAM"")"),1.6660139999999999) -> 1.666014
A22: Botsvana | B22: Botswana | C22: BW | D22: BWP | E22: 0.4 | F22: D | G22: =Dashboard!$B$3 -> 1 | H22: =MAX(Dashboard!$B$4,G22*E22) -> 0.49 | I22: 1 | J22: =IFERROR(__xludf.DUMMYFUNCTION("GOOGLEFINANCE(""CURRENCY:USDBWP"")"),13.49984) -> 13.49984 | K22: =H22*I22*J22 -> 6.6149216 | M22: =IF(L22="TRY_TIERS",IF(K22<25,19,IF(K22<35,29,IF(K22<45,39,IF(K22<60,49,79)))), IF(L22="INR_TIERS",IF(K22<40,29,IF(K22<70,49,99)), IF(L22="BRL_90",IF(K22<3,2.9,IF(K22<6,4.9,IF(K22<10,6.9,9.9))), IF(L22="IDR_000",ROUND(K22/1000,0)*1000, IF(L22="JPY_00",ROUND(K22/100,0)*100, IF(L22="KRW_000",ROUND(K22/1000,0)*1000, IF(L22="VND_000",ROUND(K22/1000,0)*1000, IF(OR(L22="USD_99",L22="EUR_99",L22="GBP_99",L22="CAD_99",L22="AUD_99",L22="PLN_99"),MAX(0.49,ROUND(K22,0)-0.01), IF(L22="MXN_00",ROUND(K22,0),IF(L22="THB_00",ROUND(K22,0),ROUND(K22,2))))))))))) -> 6.61 | N22: =M22/J22 -> 0.48963543 | P22: =IFERROR(__xludf.DUMMYFUNCTION("GOOGLEFINANCE(""CURRENCY:USDBWP"")"),13.49984) -> 13.49984
A23: Brezilya | B23: Brazil | C23: BR | D23: BRL | E23: 0.35 | F23: =IF(E23>=0.8,"A",IF(E23>=0.6,"B",IF(E23>=0.4,"C",IF(E23>=0.2,"D","E")))) -> D | G23: =Dashboard!$B$3 -> 1 | H23: =MAX(Dashboard!$B$4,G23*E23) -> 0.49 | I23: 0.85 | J23: =IFERROR(__xludf.DUMMYFUNCTION("GOOGLEFINANCE(""CURRENCY:USDBRL"")"),4.9113) -> 4.9113 | K23: =H23*I23*J23 -> 2.0455564 | L23: BRL_90 | M23: =IF(L23="TRY_TIERS",IF(K23<25,19,IF(K23<35,29,IF(K23<45,39,IF(K23<60,49,79)))), IF(L23="INR_TIERS",IF(K23<40,29,IF(K23<70,49,99)), IF(L23="BRL_90",IF(K23<3,2.9,IF(K23<6,4.9,IF(K23<10,6.9,9.9))), IF(L23="IDR_000",ROUND(K23/1000,0)*1000, IF(L23="JPY_00",ROUND(K23/100,0)*100, IF(L23="KRW_000",ROUND(K23/1000,0)*1000, IF(L23="VND_000",ROUND(K23/1000,0)*1000, IF(OR(L23="USD_99",L23="EUR_99",L23="GBP_99",L23="CAD_99",L23="AUD_99",L23="PLN_99"),MAX(0.49,ROUND(K23,0)-0.01), IF(L23="MXN_00",ROUND(K23,0),IF(L23="THB_00",ROUND(K23,0),ROUND(K23,2))))))))))) -> 2.9 | N23: =M23/J23 -> 0.59047503 | O23: =IF(N23<Dashboard!$B$4,"Below global min",IF(AND(E23>=0.8,N23<Dashboard!$B$5),"Raise high-PPP floor","OK")) -> OK | P23: =IFERROR(__xludf.DUMMYFUNCTION("GOOGLEFINANCE(""CURRENCY:USDBRL"")"),4.9113) -> 4.9113
A24: Bulgaristan | B24: Bulgaria | C24: BG | D24: BGN | E24: 0.4 | F24: D | G24: =Dashboard!$B$3 -> 1 | H24: =MAX(Dashboard!$B$4,G24*E24) -> 0.49 | I24: 1 | J24: =IFERROR(__xludf.DUMMYFUNCTION("GOOGLEFINANCE(""CURRENCY:USDBGN"")"),"#N/A") -> #N/A | K24: =H24*I24*J24 -> #N/A | M24: =IF(L24="TRY_TIERS",IF(K24<25,19,IF(K24<35,29,IF(K24<45,39,IF(K24<60,49,79)))), IF(L24="INR_TIERS",IF(K24<40,29,IF(K24<70,49,99)), IF(L24="BRL_90",IF(K24<3,2.9,IF(K24<6,4.9,IF(K24<10,6.9,9.9))), IF(L24="IDR_000",ROUND(K24/1000,0)*1000, IF(L24="JPY_00",ROUND(K24/100,0)*100, IF(L24="KRW_000",ROUND(K24/1000,0)*1000, IF(L24="VND_000",ROUND(K24/1000,0)*1000, IF(OR(L24="USD_99",L24="EUR_99",L24="GBP_99",L24="CAD_99",L24="AUD_99",L24="PLN_99"),MAX(0.49,ROUND(K24,0)-0.01), IF(L24="MXN_00",ROUND(K24,0),IF(L24="THB_00",ROUND(K24,0),ROUND(K24,2))))))))))) -> #N/A | N24: =M24/J24 -> #N/A | P24: =IFERROR(__xludf.DUMMYFUNCTION("GOOGLEFINANCE(""CURRENCY:USDBGN"")"),"#N/A") -> #N/A
A25: Burkina Faso | B25: Burkina Faso | C25: BF | D25: XOF | E25: 0.18 | F25: E | G25: =Dashboard!$B$3 -> 1 | H25: =MAX(Dashboard!$B$4,G25*E25) -> 0.49 | I25: 1 | J25: =IFERROR(__xludf.DUMMYFUNCTION("GOOGLEFINANCE(""CURRENCY:USDXOF"")"),558.7654) -> 558.7654 | K25: =H25*I25*J25 -> 273.79505 | M25: =IF(L25="TRY_TIERS",IF(K25<25,19,IF(K25<35,29,IF(K25<45,39,IF(K25<60,49,79)))), IF(L25="INR_TIERS",IF(K25<40,29,IF(K25<70,49,99)), IF(L25="BRL_90",IF(K25<3,2.9,IF(K25<6,4.9,IF(K25<10,6.9,9.9))), IF(L25="IDR_000",ROUND(K25/1000,0)*1000, IF(L25="JPY_00",ROUND(K25/100,0)*100, IF(L25="KRW_000",ROUND(K25/1000,0)*1000, IF(L25="VND_000",ROUND(K25/1000,0)*1000, IF(OR(L25="USD_99",L25="EUR_99",L25="GBP_99",L25="CAD_99",L25="AUD_99",L25="PLN_99"),MAX(0.49,ROUND(K25,0)-0.01), IF(L25="MXN_00",ROUND(K25,0),IF(L25="THB_00",ROUND(K25,0),ROUND(K25,2))))))))))) -> 273.8 | N25: =M25/J25 -> 0.49000887 | P25: =IFERROR(__xludf.DUMMYFUNCTION("GOOGLEFINANCE(""CURRENCY:USDXOF"")"),558.7654) -> 558.7654
A26: Cabo Verde | B26: Cabo Verde | C26: CV | D26: CVE | E26: 0.3 | F26: D | G26: =Dashboard!$B$3 -> 1 | H26: =MAX(Dashboard!$B$4,G26*E26) -> 0.49 | I26: 1 | J26: =IFERROR(__xludf.DUMMYFUNCTION("GOOGLEFINANCE(""CURRENCY:USDCVE"")"),93.92769000000001) -> 93.92769 | K26: =H26*I26*J26 -> 46.024568 | M26: =IF(L26="TRY_TIERS",IF(K26<25,19,IF(K26<35,29,IF(K26<45,39,IF(K26<60,49,79)))), IF(L26="INR_TIERS",IF(K26<40,29,IF(K26<70,49,99)), IF(L26="BRL_90",IF(K26<3,2.9,IF(K26<6,4.9,IF(K26<10,6.9,9.9))), IF(L26="IDR_000",ROUND(K26/1000,0)*1000, IF(L26="JPY_00",ROUND(K26/100,0)*100, IF(L26="KRW_000",ROUND(K26/1000,0)*1000, IF(L26="VND_000",ROUND(K26/1000,0)*1000, IF(OR(L26="USD_99",L26="EUR_99",L26="GBP_99",L26="CAD_99",L26="AUD_99",L26="PLN_99"),MAX(0.49,ROUND(K26,0)-0.01), IF(L26="MXN_00",ROUND(K26,0),IF(L26="THB_00",ROUND(K26,0),ROUND(K26,2))))))))))) -> 46.02 | N26: =M26/J26 -> 0.48995137 | P26: =IFERROR(__xludf.DUMMYFUNCTION("GOOGLEFINANCE(""CURRENCY:USDCVE"")"),93.92769000000001) -> 93.92769
A27: Kamboçya | B27: Cambodia | C27: KH | D27: KHR | E27: 0.2 | F27: E | G27: =Dashboard!$B$3 -> 1 | H27: =MAX(Dashboard!$B$4,G27*E27) -> 0.49 | I27: 1 | J27: =IFERROR(__xludf.DUMMYFUNCTION("GOOGLEFINANCE(""CURRENCY:USDKHR"")"),4012.13) -> 4012.13 | K27: =H27*I27*J27 -> 1965.9437 | M27: =IF(L27="TRY_TIERS",IF(K27<25,19,IF(K27<35,29,IF(K27<45,39,IF(K27<60,49,79)))), IF(L27="INR_TIERS",IF(K27<40,29,IF(K27<70,49,99)), IF(L27="BRL_90",IF(K27<3,2.9,IF(K27<6,4.9,IF(K27<10,6.9,9.9))), IF(L27="IDR_000",ROUND(K27/1000,0)*1000, IF(L27="JPY_00",ROUND(K27/100,0)*100, IF(L27="KRW_000",ROUND(K27/1000,0)*1000, IF(L27="VND_000",ROUND(K27/1000,0)*1000, IF(OR(L27="USD_99",L27="EUR_99",L27="GBP_99",L27="CAD_99",L27="AUD_99",L27="PLN_99"),MAX(0.49,ROUND(K27,0)-0.01), IF(L27="MXN_00",ROUND(K27,0),IF(L27="THB_00",ROUND(K27,0),ROUND(K27,2))))))))))) -> 1965.94 | N27: =M27/J27 -> 0.48999908 | P27: =IFERROR(__xludf.DUMMYFUNCTION("GOOGLEFINANCE(""CURRENCY:USDKHR"")"),4012.13) -> 4012.13
A28: Kamerun | B28: Cameroon | C28: CM | D28: XAF | E28: 0.12 | F28: E | G28: =Dashboard!$B$3 -> 1 | H28: =MAX(Dashboard!$B$4,G28*E28) -> 0.49 | I28: 1 | J28: =IFERROR(__xludf.DUMMYFUNCTION("GOOGLEFINANCE(""CURRENCY:USDXAF"")"),558.7654) -> 558.7654 | K28: =H28*I28*J28 -> 273.79505 | M28: =IF(L28="TRY_TIERS",IF(K28<25,19,IF(K28<35,29,IF(K28<45,39,IF(K28<60,49,79)))), IF(L28="INR_TIERS",IF(K28<40,29,IF(K28<70,49,99)), IF(L28="BRL_90",IF(K28<3,2.9,IF(K28<6,4.9,IF(K28<10,6.9,9.9))), IF(L28="IDR_000",ROUND(K28/1000,0)*1000, IF(L28="JPY_00",ROUND(K28/100,0)*100, IF(L28="KRW_000",ROUND(K28/1000,0)*1000, IF(L28="VND_000",ROUND(K28/1000,0)*1000, IF(OR(L28="USD_99",L28="EUR_99",L28="GBP_99",L28="CAD_99",L28="AUD_99",L28="PLN_99"),MAX(0.49,ROUND(K28,0)-0.01), IF(L28="MXN_00",ROUND(K28,0),IF(L28="THB_00",ROUND(K28,0),ROUND(K28,2))))))))))) -> 273.8 | N28: =M28/J28 -> 0.49000887 | P28: =IFERROR(__xludf.DUMMYFUNCTION("GOOGLEFINANCE(""CURRENCY:USDXAF"")"),558.7654) -> 558.7654
A29: Kanada | B29: Canada | C29: CA | D29: CAD | E29: 0.85 | F29: =IF(E29>=0.8,"A",IF(E29>=0.6,"B",IF(E29>=0.4,"C",IF(E29>=0.2,"D","E")))) -> A | G29: =Dashboard!$B$3 -> 1 | H29: =MAX(Dashboard!$B$4,G29*E29) -> 0.85 | I29: 1 | J29: =IFERROR(__xludf.DUMMYFUNCTION("GOOGLEFINANCE(""CURRENCY:USDCAD"")"),1.369425) -> 1.369425 | K29: =H29*I29*J29 -> 1.1640112 | L29: CAD_99 | M29: =IF(L29="TRY_TIERS",IF(K29<25,19,IF(K29<35,29,IF(K29<45,39,IF(K29<60,49,79)))), IF(L29="INR_TIERS",IF(K29<40,29,IF(K29<70,49,99)), IF(L29="BRL_90",IF(K29<3,2.9,IF(K29<6,4.9,IF(K29<10,6.9,9.9))), IF(L29="IDR_000",ROUND(K29/1000,0)*1000, IF(L29="JPY_00",ROUND(K29/100,0)*100, IF(L29="KRW_000",ROUND(K29/1000,0)*1000, IF(L29="VND_000",ROUND(K29/1000,0)*1000, IF(OR(L29="USD_99",L29="EUR_99",L29="GBP_99",L29="CAD_99",L29="AUD_99",L29="PLN_99"),MAX(0.49,ROUND(K29,0)-0.01), IF(L29="MXN_00",ROUND(K29,0),IF(L29="THB_00",ROUND(K29,0),ROUND(K29,2))))))))))) -> 0.99 | N29: =M29/J29 -> 0.72293116 | O29: =IF(N29<Dashboard!$B$4,"Below global min",IF(AND(E29>=0.8,N29<Dashboard!$B$5),"Raise high-PPP floor","OK")) -> Raise high-PPP floor | P29: =IFERROR(__xludf.DUMMYFUNCTION("GOOGLEFINANCE(""CURRENCY:USDCAD"")"),1.369425) -> 1.369425
A30: Cayman Adaları | B30: Cayman Islands | C30: KY | D30: KYD | E30: 1 | F30: A | G30: =Dashboard!$B$3 -> 1 | H30: =MAX(Dashboard!$B$4,G30*E30) -> 1 | I30: 1 | J30: =IFERROR(__xludf.DUMMYFUNCTION("GOOGLEFINANCE(""CURRENCY:USDKYD"")"),0.8334256) -> 0.8334256 | K30: =H30*I30*J30 -> 0.8334256 | M30: =IF(L30="TRY_TIERS",IF(K30<25,19,IF(K30<35,29,IF(K30<45,39,IF(K30<60,49,79)))), IF(L30="INR_TIERS",IF(K30<40,29,IF(K30<70,49,99)), IF(L30="BRL_90",IF(K30<3,2.9,IF(K30<6,4.9,IF(K30<10,6.9,9.9))), IF(L30="IDR_000",ROUND(K30/1000,0)*1000, IF(L30="JPY_00",ROUND(K30/100,0)*100, IF(L30="KRW_000",ROUND(K30/1000,0)*1000, IF(L30="VND_000",ROUND(K30/1000,0)*1000, IF(OR(L30="USD_99",L30="EUR_99",L30="GBP_99",L30="CAD_99",L30="AUD_99",L30="PLN_99"),MAX(0.49,ROUND(K30,0)-0.01), IF(L30="MXN_00",ROUND(K30,0),IF(L30="THB_00",ROUND(K30,0),ROUND(K30,2))))))))))) -> 0.83 | N30: =M30/J30 -> 0.99588974 | P30: =IFERROR(__xludf.DUMMYFUNCTION("GOOGLEFINANCE(""CURRENCY:USDKYD"")"),0.8334256) -> 0.8334256
A31: Orta Afrika Cumhuriyeti | B31: Central African Republic | C31: CF | D31: XAF | E31: 0.12 | F31: E | G31: =Dashboard!$B$3 -> 1 | H31: =MAX(Dashboard!$B$4,G31*E31) -> 0.49 | I31: 1 | J31: =IFERROR(__xludf.DUMMYFUNCTION("GOOGLEFINANCE(""CURRENCY:USDXAF"")"),558.7654) -> 558.7654 | K31: =H31*I31*J31 -> 273.79505 | M31: =IF(L31="TRY_TIERS",IF(K31<25,19,IF(K31<35,29,IF(K31<45,39,IF(K31<60,49,79)))), IF(L31="INR_TIERS",IF(K31<40,29,IF(K31<70,49,99)), IF(L31="BRL_90",IF(K31<3,2.9,IF(K31<6,4.9,IF(K31<10,6.9,9.9))), IF(L31="IDR_000",ROUND(K31/1000,0)*1000, IF(L31="JPY_00",ROUND(K31/100,0)*100, IF(L31="KRW_000",ROUND(K31/1000,0)*1000, IF(L31="VND_000",ROUND(K31/1000,0)*1000, IF(OR(L31="USD_99",L31="EUR_99",L31="GBP_99",L31="CAD_99",L31="AUD_99",L31="PLN_99"),MAX(0.49,ROUND(K31,0)-0.01), IF(L31="MXN_00",ROUND(K31,0),IF(L31="THB_00",ROUND(K31,0),ROUND(K31,2))))))))))) -> 273.8 | N31: =M31/J31 -> 0.49000887 | P31: =IFERROR(__xludf.DUMMYFUNCTION("GOOGLEFINANCE(""CURRENCY:USDXAF"")"),558.7654) -> 558.7654
A32: Çad | B32: Chad | C32: TD | D32: XAF | E32: 0.12 | F32: E | G32: =Dashboard!$B$3 -> 1 | H32: =MAX(Dashboard!$B$4,G32*E32) -> 0.49 | I32: 1 | J32: =IFERROR(__xludf.DUMMYFUNCTION("GOOGLEFINANCE(""CURRENCY:USDXAF"")"),558.7654) -> 558.7654 | K32: =H32*I32*J32 -> 273.79505 | M32: =IF(L32="TRY_TIERS",IF(K32<25,19,IF(K32<35,29,IF(K32<45,39,IF(K32<60,49,79)))), IF(L32="INR_TIERS",IF(K32<40,29,IF(K32<70,49,99)), IF(L32="BRL_90",IF(K32<3,2.9,IF(K32<6,4.9,IF(K32<10,6.9,9.9))), IF(L32="IDR_000",ROUND(K32/1000,0)*1000, IF(L32="JPY_00",ROUND(K32/100,0)*100, IF(L32="KRW_000",ROUND(K32/1000,0)*1000, IF(L32="VND_000",ROUND(K32/1000,0)*1000, IF(OR(L32="USD_99",L32="EUR_99",L32="GBP_99",L32="CAD_99",L32="AUD_99",L32="PLN_99"),MAX(0.49,ROUND(K32,0)-0.01), IF(L32="MXN_00",ROUND(K32,0),IF(L32="THB_00",ROUND(K32,0),ROUND(K32,2))))))))))) -> 273.8 | N32: =M32/J32 -> 0.49000887 | P32: =IFERROR(__xludf.DUMMYFUNCTION("GOOGLEFINANCE(""CURRENCY:USDXAF"")"),558.7654) -> 558.7654
A33: Şili | B33: Chile | C33: CL | D33: CLP | E33: 0.6 | F33: C | G33: =Dashboard!$B$3 -> 1 | H33: =MAX(Dashboard!$B$4,G33*E33) -> 0.6 | I33: 1 | J33: =IFERROR(__xludf.DUMMYFUNCTION("GOOGLEFINANCE(""CURRENCY:USDCLP"")"),892.857143) -> 892.85714 | K33: =H33*I33*J33 -> 535.71429 | M33: =IF(L33="TRY_TIERS",IF(K33<25,19,IF(K33<35,29,IF(K33<45,39,IF(K33<60,49,79)))), IF(L33="INR_TIERS",IF(K33<40,29,IF(K33<70,49,99)), IF(L33="BRL_90",IF(K33<3,2.9,IF(K33<6,4.9,IF(K33<10,6.9,9.9))), IF(L33="IDR_000",ROUND(K33/1000,0)*1000, IF(L33="JPY_00",ROUND(K33/100,0)*100, IF(L33="KRW_000",ROUND(K33/1000,0)*1000, IF(L33="VND_000",ROUND(K33/1000,0)*1000, IF(OR(L33="USD_99",L33="EUR_99",L33="GBP_99",L33="CAD_99",L33="AUD_99",L33="PLN_99"),MAX(0.49,ROUND(K33,0)-0.01), IF(L33="MXN_00",ROUND(K33,0),IF(L33="THB_00",ROUND(K33,0),ROUND(K33,2))))))))))) -> 535.71 | N33: =M33/J33 -> 0.5999952 | P33: =IFERROR(__xludf.DUMMYFUNCTION("GOOGLEFINANCE(""CURRENCY:USDCLP"")"),892.857143) -> 892.85714
A34: Kolombiya | B34: Colombia | C34: CO | D34: COP-COU | E34: 0.38 | F34: D | G34: =Dashboard!$B$3 -> 1 | H34: =MAX(Dashboard!$B$4,G34*E34) -> 0.49 | I34: 1 | J34: =IFERROR(__xludf.DUMMYFUNCTION("GOOGLEFINANCE(""CURRENCY:USDCOP"")"),3752.41843) -> 3752.4184 | K34: =H34*I34*J34 -> 1838.685 | M34: =IF(L34="TRY_TIERS",IF(K34<25,19,IF(K34<35,29,IF(K34<45,39,IF(K34<60,49,79)))), IF(L34="INR_TIERS",IF(K34<40,29,IF(K34<70,49,99)), IF(L34="BRL_90",IF(K34<3,2.9,IF(K34<6,4.9,IF(K34<10,6.9,9.9))), IF(L34="IDR_000",ROUND(K34/1000,0)*1000, IF(L34="JPY_00",ROUND(K34/100,0)*100, IF(L34="KRW_000",ROUND(K34/1000,0)*1000, IF(L34="VND_000",ROUND(K34/1000,0)*1000, IF(OR(L34="USD_99",L34="EUR_99",L34="GBP_99",L34="CAD_99",L34="AUD_99",L34="PLN_99"),MAX(0.49,ROUND(K34,0)-0.01), IF(L34="MXN_00",ROUND(K34,0),IF(L34="THB_00",ROUND(K34,0),ROUND(K34,2))))))))))) -> 1838.69 | N34: =M34/J34 -> 0.49000132 | P34: =IFERROR(__xludf.DUMMYFUNCTION("GOOGLEFINANCE(""CURRENCY:USDCOP"")"),3752.41843) -> 3752.4184
A35: Komorlar | B35: Comoros | C35: KM | D35: KMF | E35: 0.18 | F35: E | G35: =Dashboard!$B$3 -> 1 | H35: =MAX(Dashboard!$B$4,G35*E35) -> 0.49 | I35: 1 | J35: =IFERROR(__xludf.DUMMYFUNCTION("GOOGLEFINANCE(""CURRENCY:USDKMF"")"),420.0) -> 420 | K35: =H35*I35*J35 -> 205.8 | M35: =IF(L35="TRY_TIERS",IF(K35<25,19,IF(K35<35,29,IF(K35<45,39,IF(K35<60,49,79)))), IF(L35="INR_TIERS",IF(K35<40,29,IF(K35<70,49,99)), IF(L35="BRL_90",IF(K35<3,2.9,IF(K35<6,4.9,IF(K35<10,6.9,9.9))), IF(L35="IDR_000",ROUND(K35/1000,0)*1000, IF(L35="JPY_00",ROUND(K35/100,0)*100, IF(L35="KRW_000",ROUND(K35/1000,0)*1000, IF(L35="VND_000",ROUND(K35/1000,0)*1000, IF(OR(L35="USD_99",L35="EUR_99",L35="GBP_99",L35="CAD_99",L35="AUD_99",L35="PLN_99"),MAX(0.49,ROUND(K35,0)-0.01), IF(L35="MXN_00",ROUND(K35,0),IF(L35="THB_00",ROUND(K35,0),ROUND(K35,2))))))))))) -> 205.8 | N35: =M35/J35 -> 0.49 | P35: =IFERROR(__xludf.DUMMYFUNCTION("GOOGLEFINANCE(""CURRENCY:USDKMF"")"),420.0) -> 420
A36: Kongo-Brazavil | B36: Congo | C36: CG | D36: XAF | E36: 0.22 | F36: E | G36: =Dashboard!$B$3 -> 1 | H36: =MAX(Dashboard!$B$4,G36*E36) -> 0.49 | I36: 1 | J36: =IFERROR(__xludf.DUMMYFUNCTION("GOOGLEFINANCE(""CURRENCY:USDXAF"")"),558.7654) -> 558.7654 | K36: =H36*I36*J36 -> 273.79505 | M36: =IF(L36="TRY_TIERS",IF(K36<25,19,IF(K36<35,29,IF(K36<45,39,IF(K36<60,49,79)))), IF(L36="INR_TIERS",IF(K36<40,29,IF(K36<70,49,99)), IF(L36="BRL_90",IF(K36<3,2.9,IF(K36<6,4.9,IF(K36<10,6.9,9.9))), IF(L36="IDR_000",ROUND(K36/1000,0)*1000, IF(L36="JPY_00",ROUND(K36/100,0)*100, IF(L36="KRW_000",ROUND(K36/1000,0)*1000, IF(L36="VND_000",ROUND(K36/1000,0)*1000, IF(OR(L36="USD_99",L36="EUR_99",L36="GBP_99",L36="CAD_99",L36="AUD_99",L36="PLN_99"),MAX(0.49,ROUND(K36,0)-0.01), IF(L36="MXN_00",ROUND(K36,0),IF(L36="THB_00",ROUND(K36,0),ROUND(K36,2))))))))))) -> 273.8 | N36: =M36/J36 -> 0.49000887 | P36: =IFERROR(__xludf.DUMMYFUNCTION("GOOGLEFINANCE(""CURRENCY:USDXAF"")"),558.7654) -> 558.7654
A37: Kongo-Kinşasa | B37: Congo (the Democratic Republic of the) | C37: CD | D37: CDF | E37: 0.15 | F37: E | G37: =Dashboard!$B$3 -> 1 | H37: =MAX(Dashboard!$B$4,G37*E37) -> 0.49 | I37: 1 | J37: =IFERROR(__xludf.DUMMYFUNCTION("GOOGLEFINANCE(""CURRENCY:USDCDF"")"),2280.07117) -> 2280.0712 | K37: =H37*I37*J37 -> 1117.2349 | M37: =IF(L37="TRY_TIERS",IF(K37<25,19,IF(K37<35,29,IF(K37<45,39,IF(K37<60,49,79)))), IF(L37="INR_TIERS",IF(K37<40,29,IF(K37<70,49,99)), IF(L37="BRL_90",IF(K37<3,2.9,IF(K37<6,4.9,IF(K37<10,6.9,9.9))), IF(L37="IDR_000",ROUND(K37/1000,0)*1000, IF(L37="JPY_00",ROUND(K37/100,0)*100, IF(L37="KRW_000",ROUND(K37/1000,0)*1000, IF(L37="VND_000",ROUND(K37/1000,0)*1000, IF(OR(L37="USD_99",L37="EUR_99",L37="GBP_99",L37="CAD_99",L37="AUD_99",L37="PLN_99"),MAX(0.49,ROUND(K37,0)-0.01), IF(L37="MXN_00",ROUND(K37,0),IF(L37="THB_00",ROUND(K37,0),ROUND(K37,2))))))))))) -> 1117.23 | N37: =M37/J37 -> 0.48999786 | P37: =IFERROR(__xludf.DUMMYFUNCTION("GOOGLEFINANCE(""CURRENCY:USDCDF"")"),2280.07117) -> 2280.0712
A38: KostaRika | B38: Costa Rica | C38: CR | D38: CRC | E38: 0.5 | F38: C | G38: =Dashboard!$B$3 -> 1 | H38: =MAX(Dashboard!$B$4,G38*E38) -> 0.5 | I38: 1 | J38: =IFERROR(__xludf.DUMMYFUNCTION("GOOGLEFINANCE(""CURRENCY:USDCRC"")"),456.4117) -> 456.4117 | K38: =H38*I38*J38 -> 228.20585 | M38: =IF(L38="TRY_TIERS",IF(K38<25,19,IF(K38<35,29,IF(K38<45,39,IF(K38<60,49,79)))), IF(L38="INR_TIERS",IF(K38<40,29,IF(K38<70,49,99)), IF(L38="BRL_90",IF(K38<3,2.9,IF(K38<6,4.9,IF(K38<10,6.9,9.9))), IF(L38="IDR_000",ROUND(K38/1000,0)*1000, IF(L38="JPY_00",ROUND(K38/100,0)*100, IF(L38="KRW_000",ROUND(K38/1000,0)*1000, IF(L38="VND_000",ROUND(K38/1000,0)*1000, IF(OR(L38="USD_99",L38="EUR_99",L38="GBP_99",L38="CAD_99",L38="AUD_99",L38="PLN_99"),MAX(0.49,ROUND(K38,0)-0.01), IF(L38="MXN_00",ROUND(K38,0),IF(L38="THB_00",ROUND(K38,0),ROUND(K38,2))))))))))) -> 228.21 | N38: =M38/J38 -> 0.50000909 | P38: =IFERROR(__xludf.DUMMYFUNCTION("GOOGLEFINANCE(""CURRENCY:USDCRC"")"),456.4117) -> 456.4117
A39: Côte d’Ivoire | B39: Côte d’Ivoire | C39: CI | D39: XOF | E39: 0.25 | F39: E | G39: =Dashboard!$B$3 -> 1 | H39: =MAX(Dashboard!$B$4,G39*E39) -> 0.49 | I39: 1 | J39: =IFERROR(__xludf.DUMMYFUNCTION("GOOGLEFINANCE(""CURRENCY:USDXOF"")"),558.7654) -> 558.7654 | K39: =H39*I39*J39 -> 273.79505 | M39: =IF(L39="TRY_TIERS",IF(K39<25,19,IF(K39<35,29,IF(K39<45,39,IF(K39<60,49,79)))), IF(L39="INR_TIERS",IF(K39<40,29,IF(K39<70,49,99)), IF(L39="BRL_90",IF(K39<3,2.9,IF(K39<6,4.9,IF(K39<10,6.9,9.9))), IF(L39="IDR_000",ROUND(K39/1000,0)*1000, IF(L39="JPY_00",ROUND(K39/100,0)*100, IF(L39="KRW_000",ROUND(K39/1000,0)*1000, IF(L39="VND_000",ROUND(K39/1000,0)*1000, IF(OR(L39="USD_99",L39="EUR_99",L39="GBP_99",L39="CAD_99",L39="AUD_99",L39="PLN_99"),MAX(0.49,ROUND(K39,0)-0.01), IF(L39="MXN_00",ROUND(K39,0),IF(L39="THB_00",ROUND(K39,0),ROUND(K39,2))))))))))) -> 273.8 | N39: =M39/J39 -> 0.49000887 | P39: =IFERROR(__xludf.DUMMYFUNCTION("GOOGLEFINANCE(""CURRENCY:USDXOF"")"),558.7654) -> 558.7654
A40: Hırvatistan | B40: Croaita | C40: HR | D40: EUR | E40: 0.55 | F40: C | G40: =Dashboard!$B$3 -> 1 | H40: =MAX(Dashboard!$B$4,G40*E40) -> 0.55 | I40: 1 | J40: =IFERROR(__xludf.DUMMYFUNCTION("GOOGLEFINANCE(""CURRENCY:USDEUR"")"),0.8519) -> 0.8519 | K40: =H40*I40*J40 -> 0.468545 | M40: =IF(L40="TRY_TIERS",IF(K40<25,19,IF(K40<35,29,IF(K40<45,39,IF(K40<60,49,79)))), IF(L40="INR_TIERS",IF(K40<40,29,IF(K40<70,49,99)), IF(L40="BRL_90",IF(K40<3,2.9,IF(K40<6,4.9,IF(K40<10,6.9,9.9))), IF(L40="IDR_000",ROUND(K40/1000,0)*1000, IF(L40="JPY_00",ROUND(K40/100,0)*100, IF(L40="KRW_000",ROUND(K40/1000,0)*1000, IF(L40="VND_000",ROUND(K40/1000,0)*1000, IF(OR(L40="USD_99",L40="EUR_99",L40="GBP_99",L40="CAD_99",L40="AUD_99",L40="PLN_99"),MAX(0.49,ROUND(K40,0)-0.01), IF(L40="MXN_00",ROUND(K40,0),IF(L40="THB_00",ROUND(K40,0),ROUND(K40,2))))))))))) -> 0.47 | N40: =M40/J40 -> 0.55170795 | P40: =IFERROR(__xludf.DUMMYFUNCTION("GOOGLEFINANCE(""CURRENCY:USDEUR"")"),0.8519) -> 0.8519
...

Sheet countries
A1: S | B1: A | C1: B | D1: C | E1: D | F1: S | G1: 1.00
A2: Australia | B2: Austria | C2: Argentina | D2: Bangladesh | E2: Central African Republic | F2: A | G2: 0.80
A3: Canada | B3: Belgium | C3: Brazil | D3: Egypt | E3: Chad | F3: B | G3: 0.55
A4: Denmark | B4: Czech Republic | C4: Chile | D4: India | E4: Eritrea | F4: C | G4: 0.30
A5: France | B5: Finland | C5: Colombia | D5: Indonesia | E5: Liberia | F5: D | G5: 0.25
A6: Germany | B6: Ireland | C6: Hungary | D6: Nigeria | E6: Niger
A7: Japan | B7: Israel | C7: Malaysia | D7: Pakistan | E7: Sierra Leone
A8: Netherlands | B8: Italy | C8: Mexico | D8: Philippines | E8: Somalia
A9: New Zealand | B9: Poland | C9: Romania | D9: Vietnam
A10: Norway | B10: Portugal | C10: South Africa
A11: Singapore | B11: Saudi Arabia | C11: Thailand
A12: South Korea | B12: Spain | C12: Turkey
A13: Sweden | B13: Taiwan
A14: Switzerland
A15: UAE
A16: UK
A17: USA

Sheet PriceLast
D1: Currency | E1: PPP | F1: TIER | G1: MAX | H1: MIN | I1: TIER CONST | J1: $ | K1: USD/LOCAL CUR. | L1: LOCAL | M1: FLG
A2: Arnavutluk | B2: Albania | C2: AL | D2: ALL | E2: 0.35 | F2: D | G2: 3 | H2: 1.49 | I2: =IF(F2="S",1,IF(F2="A",0.8,IF(F2="B",0.55,IF(F2="C",0.3,IF(F2="D",0.25,0.25))))) -> 0.25 | J2: =MAX(H2,G2*I2) -> 1.49 | K2: =IFERROR(__xludf.DUMMYFUNCTION("GOOGLEFINANCE(""CURRENCY:USDALL"")"),81.26480000000001) -> 81.2648 | L2: =J2*K2 -> 121.08455 | M2: 119
A3: Cezayir | B3: Algeria | C3: DZ | D3: DZD | E3: 0.28 | F3: D | G3: 3 | H3: 1.49 | I3: =IF(F3="S",1,IF(F3="A",0.8,IF(F3="B",0.55,IF(F3="C",0.3,IF(F3="D",0.25,0.25))))) -> 0.25 | J3: =MAX(H3,G3*I3) -> 1.49 | K3: =IFERROR(__xludf.DUMMYFUNCTION("GOOGLEFINANCE(""CURRENCY:USDDZD"")"),132.3826) -> 132.3826 | L3: =J3*K3 -> 197.25007 | M3: 189
A4: Angola | B4: Angola | C4: AO | D4: AOA | E4: 0.22 | F4: D | G4: 3 | H4: 1.49 | I4: =IF(F4="S",1,IF(F4="A",0.8,IF(F4="B",0.55,IF(F4="C",0.3,IF(F4="D",0.25,0.25))))) -> 0.25 | J4: =MAX(H4,G4*I4) -> 1.49 | K4: =IFERROR(__xludf.DUMMYFUNCTION("GOOGLEFINANCE(""CURRENCY:USDAOA"")"),918.0) -> 918 | L4: =J4*K4 -> 1367.82 | M4: 1290
A5: Antigua ve Barbuda | B5: Antigua and Barbuda | C5: AG | D5: XCD | E5: 0.65 | F5: B | G5: 3 | H5: 1.49 | I5: =IF(F5="S",1,IF(F5="A",0.8,IF(F5="B",0.55,IF(F5="C",0.3,IF(F5="D",0.25,0.25))))) -> 0.55 | J5: =MAX(H5,G5*I5) -> 1.65 | K5: =IFERROR(__xludf.DUMMYFUNCTION("GOOGLEFINANCE(""CURRENCY:USDXCD"")"),2.70255) -> 2.70255 | L5: =J5*K5 -> 4.4592075 | M5: 3.9
A6: Arjantin | B6: Argentina | C6: AR | D6: ARS | E6: 0.3 | F6: B | G6: 3 | H6: 1.49 | I6: =IF(F6="S",1,IF(F6="A",0.8,IF(F6="B",0.55,IF(F6="C",0.3,IF(F6="D",0.25,0.25))))) -> 0.55 | J6: =MAX(H6,G6*I6) -> 1.65 | K6: =IFERROR(__xludf.DUMMYFUNCTION("GOOGLEFINANCE(""CURRENCY:USDARS"")"),1385.0) -> 1385 | L6: =J6*K6 -> 2285.25 | M6: 1990
A7: Ermenistan | B7: Armenia | C7: AM | D7: AMD | E7: 0.3 | F7: D | G7: 3 | H7: 1.49 | I7: =IF(F7="S",1,IF(F7="A",0.8,IF(F7="B",0.55,IF(F7="C",0.3,IF(F7="D",0.25,0.25))))) -> 0.25 | J7: =MAX(H7,G7*I7) -> 1.49 | K7: =IFERROR(__xludf.DUMMYFUNCTION("GOOGLEFINANCE(""CURRENCY:USDAMD"")"),368.0783) -> 368.0783 | L7: =J7*K7 -> 548.43667 | M7: 539
A8: Aruba | B8: Aruba | C8: AW | D8: AWG | E8: 0.75 | F8: A | G8: 3 | H8: 1.49 | I8: =IF(F8="S",1,IF(F8="A",0.8,IF(F8="B",0.55,IF(F8="C",0.3,IF(F8="D",0.25,0.25))))) -> 0.8 | J8: =MAX(H8,G8*I8) -> 2.4 | K8: =IFERROR(__xludf.DUMMYFUNCTION("GOOGLEFINANCE(""CURRENCY:USDAWG"")"),1.8025) -> 1.8025 | L8: =J8*K8 -> 4.326 | M8: 3.9
A9: Avustralya | B9: Australia | C9: AU | D9: AUD | E9: 0.95 | F9: S | G9: 3 | H9: 1.49 | I9: =IF(F9="S",1,IF(F9="A",0.8,IF(F9="B",0.55,IF(F9="C",0.3,IF(F9="D",0.25,0.25))))) -> 1 | J9: =MAX(H9,G9*I9) -> 3 | K9: =IFERROR(__xludf.DUMMYFUNCTION("GOOGLEFINANCE(""CURRENCY:USDAUD"")"),1.381082) -> 1.381082 | L9: =J9*K9 -> 4.143246 | M9: 3.9
A10: Avusturya | B10: Austria | C10: AT | D10: EUR | E10: 0.86 | F10: A | G10: 3 | H10: 1.49 | I10: =IF(F10="S",1,IF(F10="A",0.8,IF(F10="B",0.55,IF(F10="C",0.3,IF(F10="D",0.25,0.25))))) -> 0.8 | J10: =MAX(H10,G10*I10) -> 2.4 | K10: =IFERROR(__xludf.DUMMYFUNCTION("GOOGLEFINANCE(""CURRENCY:USDEUR"")"),0.8519) -> 0.8519 | L10: =J10*K10 -> 2.04456 | M10: 1.9
A11: Azerbaycan | B11: Azerbaijan | C11: AZ | D11: AZN | E11: 0.4 | F11: B | G11: 3 | H11: 1.49 | I11: =IF(F11="S",1,IF(F11="A",0.8,IF(F11="B",0.55,IF(F11="C",0.3,IF(F11="D",0.25,0.25))))) -> 0.55 | J11: =MAX(H11,G11*I11) -> 1.65 | K11: =IFERROR(__xludf.DUMMYFUNCTION("GOOGLEFINANCE(""CURRENCY:USDAZN"")"),1.7) -> 1.7 | L11: =J11*K11 -> 2.805 | M11: 2.49
A12: Bahamalar | B12: Bahamas | C12: BS | D12: BSD | E12: 0.75 | F12: A | G12: 3 | H12: 1.49 | I12: =IF(F12="S",1,IF(F12="A",0.8,IF(F12="B",0.55,IF(F12="C",0.3,IF(F12="D",0.25,0.25))))) -> 0.8 | J12: =MAX(H12,G12*I12) -> 2.4 | K12: =IFERROR(__xludf.DUMMYFUNCTION("GOOGLEFINANCE(""CURRENCY:USDBSD"")"),1.000136) -> 1.000136 | L12: =J12*K12 -> 2.4003264 | M12: 2.39
A13: Bahreyn | B13: Bahrain | C13: BH | D13: BHD | E13: 0.85 | F13: A | G13: 3 | H13: 1.49 | I13: =IF(F13="S",1,IF(F13="A",0.8,IF(F13="B",0.55,IF(F13="C",0.3,IF(F13="D",0.25,0.25))))) -> 0.8 | J13: =MAX(H13,G13*I13) -> 2.4 | K13: =IFERROR(__xludf.DUMMYFUNCTION("GOOGLEFINANCE(""CURRENCY:USDBHD"")"),0.3774469) -> 0.3774469 | L13: =J13*K13 -> 0.90587256 | M13: 0.89
A14: Bangladeş | B14: Bangladesh | C14: BD | D14: BDT | E14: 0.15 | F14: C | G14: 3 | H14: 1.49 | I14: =IF(F14="S",1,IF(F14="A",0.8,IF(F14="B",0.55,IF(F14="C",0.3,IF(F14="D",0.25,0.25))))) -> 0.3 | J14: =MAX(H14,G14*I14) -> 1.49 | K14: =IFERROR(__xludf.DUMMYFUNCTION("GOOGLEFINANCE(""CURRENCY:USDBDT"")"),122.9364) -> 122.9364 | L14: =J14*K14 -> 183.17524 | M14: 179
A15: Belarus | B15: Belarus | C15: BY | D15: BYN | E15: 0.4 | F15: B | G15: 3 | H15: 1.49 | I15: =IF(F15="S",1,IF(F15="A",0.8,IF(F15="B",0.55,IF(F15="C",0.3,IF(F15="D",0.25,0.25))))) -> 0.55 | J15: =MAX(H15,G15*I15) -> 1.65 | K15: =IFERROR(__xludf.DUMMYFUNCTION("GOOGLEFINANCE(""CURRENCY:USDBYN"")"),2.7962249999999997) -> 2.796225 | L15: =J15*K15 -> 4.6137713 | M15: 3.9
A16: Belçika | B16: Belgium | C16: BE | D16: EUR | E16: 0.84 | F16: A | G16: 3 | H16: 1.49 | I16: =IF(F16="S",1,IF(F16="A",0.8,IF(F16="B",0.55,IF(F16="C",0.3,IF(F16="D",0.25,0.25))))) -> 0.8 | J16: =MAX(H16,G16*I16) -> 2.4 | K16: =IFERROR(__xludf.DUMMYFUNCTION("GOOGLEFINANCE(""CURRENCY:USDEUR"")"),0.8519) -> 0.8519 | L16: =J16*K16 -> 2.04456 | M16: 1.9
A17: Belize | B17: Belize | C17: BZ | D17: BZD | E17: 0.35 | F17: C | G17: 3 | H17: 1.49 | I17: =IF(F17="S",1,IF(F17="A",0.8,IF(F17="B",0.55,IF(F17="C",0.3,IF(F17="D",0.25,0.25))))) -> 0.3 | J17: =MAX(H17,G17*I17) -> 1.49 | K17: =IFERROR(__xludf.DUMMYFUNCTION("GOOGLEFINANCE(""CURRENCY:USDBZD"")"),2.011432) -> 2.011432 | L17: =J17*K17 -> 2.9970337 | M17: 2.9
A18: Benin | B18: Benin | C18: BJ | D18: XOF | E18: 0.18 | F18: D | G18: 3 | H18: 1.49 | I18: =IF(F18="S",1,IF(F18="A",0.8,IF(F18="B",0.55,IF(F18="C",0.3,IF(F18="D",0.25,0.25))))) -> 0.25 | J18: =MAX(H18,G18*I18) -> 1.49 | K18: =IFERROR(__xludf.DUMMYFUNCTION("GOOGLEFINANCE(""CURRENCY:USDXOF"")"),558.7654) -> 558.7654 | L18: =J18*K18 -> 832.56045 | M18: 790
A19: Bermuda | B19: Bermuda | C19: BM | D19: BMD | E19: 1 | F19: A | G19: 3 | H19: 1.49 | I19: =IF(F19="S",1,IF(F19="A",0.8,IF(F19="B",0.55,IF(F19="C",0.3,IF(F19="D",0.25,0.25))))) -> 0.8 | J19: =MAX(H19,G19*I19) -> 2.4 | K19: =IFERROR(__xludf.DUMMYFUNCTION("GOOGLEFINANCE(""CURRENCY:USDBMD"")"),1.0) -> 1 | L19: =J19*K19 -> 2.4 | M19: 2.39
A20: Bolivya | B20: Bolivia | C20: BO | D20: BOB-BOV | E20: 0.3 | F20: D | G20: 3 | H20: 1.49 | I20: =IF(F20="S",1,IF(F20="A",0.8,IF(F20="B",0.55,IF(F20="C",0.3,IF(F20="D",0.25,0.25))))) -> 0.25 | J20: =MAX(H20,G20*I20) -> 1.49 | K20: =IFERROR(__xludf.DUMMYFUNCTION("GOOGLEFINANCE(""CURRENCY:USDBOB"")"),6.910945) -> 6.910945 | L20: =J20*K20 -> 10.297308 | M20: 9.9
A21: Bosna-Hersek | B21: Bosnia and Herzegovina | C21: BA | D21: BAM | E21: 0.45 | F21: B | G21: 3 | H21: 1.49 | I21: =IF(F21="S",1,IF(F21="A",0.8,IF(F21="B",0.55,IF(F21="C",0.3,IF(F21="D",0.25,0.25))))) -> 0.55 | J21: =MAX(H21,G21*I21) -> 1.65 | K21: =IFERROR(__xludf.DUMMYFUNCTION("GOOGLEFINANCE(""CURRENCY:USDBAM"")"),1.6660139999999999) -> 1.666014 | L21: =J21*K21 -> 2.7489231 | M21: 2.49
A22: Botsvana | B22: Botswana | C22: BW | D22: BWP | E22: 0.4 | F22: B | G22: 3 | H22: 1.49 | I22: =IF(F22="S",1,IF(F22="A",0.8,IF(F22="B",0.55,IF(F22="C",0.3,IF(F22="D",0.25,0.25))))) -> 0.55 | J22: =MAX(H22,G22*I22) -> 1.65 | K22: =IFERROR(__xludf.DUMMYFUNCTION("GOOGLEFINANCE(""CURRENCY:USDBWP"")"),13.49984) -> 13.49984 | L22: =J22*K22 -> 22.274736 | M22: 19.9
A23: Brezilya | B23: Brazil | C23: BR | D23: BRL | E23: 0.35 | F23: B | G23: 3 | H23: 1.49 | I23: =IF(F23="S",1,IF(F23="A",0.8,IF(F23="B",0.55,IF(F23="C",0.3,IF(F23="D",0.25,0.25))))) -> 0.55 | J23: =MAX(H23,G23*I23) -> 1.65 | K23: =IFERROR(__xludf.DUMMYFUNCTION("GOOGLEFINANCE(""CURRENCY:USDBRL"")"),4.9113) -> 4.9113 | L23: =J23*K23 -> 8.103645 | M23: 7.9
A24: Bulgaristan | B24: Bulgaria | C24: BG | D24: BGN | E24: 0.4 | F24: B | G24: 3 | H24: 1.49 | I24: =IF(F24="S",1,IF(F24="A",0.8,IF(F24="B",0.55,IF(F24="C",0.3,IF(F24="D",0.25,0.25))))) -> 0.55 | J24: =MAX(H24,G24*I24) -> 1.65 | K24: =IFERROR(__xludf.DUMMYFUNCTION("GOOGLEFINANCE(""CURRENCY:USDBGN"")"),"#N/A") -> #N/A | L24: =J24*K24 -> #N/A
A25: Burkina Faso | B25: Burkina Faso | C25: BF | D25: XOF | E25: 0.18 | F25: D | G25: 3 | H25: 1.49 | I25: =IF(F25="S",1,IF(F25="A",0.8,IF(F25="B",0.55,IF(F25="C",0.3,IF(F25="D",0.25,0.25))))) -> 0.25 | J25: =MAX(H25,G25*I25) -> 1.49 | K25: =IFERROR(__xludf.DUMMYFUNCTION("GOOGLEFINANCE(""CURRENCY:USDXOF"")"),558.7654) -> 558.7654 | L25: =J25*K25 -> 832.56045 | M25: 790
A26: Cabo Verde | B26: Cabo Verde | C26: CV | D26: CVE | E26: 0.3 | F26: D | G26: 3 | H26: 1.49 | I26: =IF(F26="S",1,IF(F26="A",0.8,IF(F26="B",0.55,IF(F26="C",0.3,IF(F26="D",0.25,0.25))))) -> 0.25 | J26: =MAX(H26,G26*I26) -> 1.49 | K26: =IFERROR(__xludf.DUMMYFUNCTION("GOOGLEFINANCE(""CURRENCY:USDCVE"")"),93.92769000000001) -> 93.92769 | L26: =J26*K26 -> 139.95226 | M26: 129
A27: Kamboçya | B27: Cambodia | C27: KH | D27: KHR | E27: 0.2 | F27: D | G27: 3 | H27: 1.49 | I27: =IF(F27="S",1,IF(F27="A",0.8,IF(F27="B",0.55,IF(F27="C",0.3,IF(F27="D",0.25,0.25))))) -> 0.25 | J27: =MAX(H27,G27*I27) -> 1.49 | K27: =IFERROR(__xludf.DUMMYFUNCTION("GOOGLEFINANCE(""CURRENCY:USDKHR"")"),4012.13) -> 4012.13 | L27: =J27*K27 -> 5978.0737 | M27: 4900
A28: Kamerun | B28: Cameroon | C28: CM | D28: XAF | E28: 0.12 | F28: D | G28: 3 | H28: 1.49 | I28: =IF(F28="S",1,IF(F28="A",0.8,IF(F28="B",0.55,IF(F28="C",0.3,IF(F28="D",0.25,0.25))))) -> 0.25 | J28: =MAX(H28,G28*I28) -> 1.49 | K28: =IFERROR(__xludf.DUMMYFUNCTION("GOOGLEFINANCE(""CURRENCY:USDXAF"")"),558.7654) -> 558.7654 | L28: =J28*K28 -> 832.56045 | M28: 790
A29: Kanada | B29: Canada | C29: CA | D29: CAD | E29: 0.95 | F29: S | G29: 3 | H29: 1.49 | I29: =IF(F29="S",1,IF(F29="A",0.8,IF(F29="B",0.55,IF(F29="C",0.3,IF(F29="D",0.25,0.25))))) -> 1 | J29: =MAX(H29,G29*I29) -> 3 | K29: =IFERROR(__xludf.DUMMYFUNCTION("GOOGLEFINANCE(""CURRENCY:USDCAD"")"),1.369425) -> 1.369425 | L29: =J29*K29 -> 4.108275 | M29: 3.9
A30: Cayman Adaları | B30: Cayman Islands | C30: KY | D30: KYD | E30: 1 | F30: S | G30: 3 | H30: 1.49 | I30: =IF(F30="S",1,IF(F30="A",0.8,IF(F30="B",0.55,IF(F30="C",0.3,IF(F30="D",0.25,0.25))))) -> 1 | J30: =MAX(H30,G30*I30) -> 3 | K30: =IFERROR(__xludf.DUMMYFUNCTION("GOOGLEFINANCE(""CURRENCY:USDKYD"")"),0.8334256) -> 0.8334256 | L30: =J30*K30 -> 2.5002768 | M30: 2.39
A31: Orta Afrika Cumhuriyeti | B31: Central African Republic | C31: CF | D31: XAF | E31: 0.12 | F31: D | G31: 3 | H31: 1.49 | I31: =IF(F31="S",1,IF(F31="A",0.8,IF(F31="B",0.55,IF(F31="C",0.3,IF(F31="D",0.25,0.25))))) -> 0.25 | J31: =MAX(H31,G31*I31) -> 1.49 | K31: =IFERROR(__xludf.DUMMYFUNCTION("GOOGLEFINANCE(""CURRENCY:USDXAF"")"),558.7654) -> 558.7654 | L31: =J31*K31 -> 832.56045 | M31: 790
A32: Çad | B32: Chad | C32: TD | D32: XAF | E32: 0.12 | F32: D | G32: 3 | H32: 1.49 | I32: =IF(F32="S",1,IF(F32="A",0.8,IF(F32="B",0.55,IF(F32="C",0.3,IF(F32="D",0.25,0.25))))) -> 0.25 | J32: =MAX(H32,G32*I32) -> 1.49 | K32: =IFERROR(__xludf.DUMMYFUNCTION("GOOGLEFINANCE(""CURRENCY:USDXAF"")"),558.7654) -> 558.7654 | L32: =J32*K32 -> 832.56045 | M32: 790
A33: Şili | B33: Chile | C33: CL | D33: CLP | E33: 0.6 | F33: B | G33: 3 | H33: 1.49 | I33: =IF(F33="S",1,IF(F33="A",0.8,IF(F33="B",0.55,IF(F33="C",0.3,IF(F33="D",0.25,0.25))))) -> 0.55 | J33: =MAX(H33,G33*I33) -> 1.65 | K33: =IFERROR(__xludf.DUMMYFUNCTION("GOOGLEFINANCE(""CURRENCY:USDCLP"")"),892.857143) -> 892.85714 | L33: =J33*K33 -> 1473.2143 | M33: 1390
A34: Kolombiya | B34: Colombia | C34: CO | D34: COP-COU | E34: 0.38 | F34: B | G34: 3 | H34: 1.49 | I34: =IF(F34="S",1,IF(F34="A",0.8,IF(F34="B",0.55,IF(F34="C",0.3,IF(F34="D",0.25,0.25))))) -> 0.55 | J34: =MAX(H34,G34*I34) -> 1.65 | K34: =IFERROR(__xludf.DUMMYFUNCTION("GOOGLEFINANCE(""CURRENCY:USDCOP"")"),3752.41843) -> 3752.4184 | L34: =J34*K34 -> 6191.4904 | M34: 5900
A35: Komorlar | B35: Comoros | C35: KM | D35: KMF | E35: 0.18 | F35: D | G35: 3 | H35: 1.49 | I35: =IF(F35="S",1,IF(F35="A",0.8,IF(F35="B",0.55,IF(F35="C",0.3,IF(F35="D",0.25,0.25))))) -> 0.25 | J35: =MAX(H35,G35*I35) -> 1.49 | K35: =IFERROR(__xludf.DUMMYFUNCTION("GOOGLEFINANCE(""CURRENCY:USDKMF"")"),420.0) -> 420 | L35: =J35*K35 -> 625.8 | M35: 590
A36: Kongo-Brazavil | B36: Congo | C36: CG | D36: XAF | E36: 0.22 | F36: D | G36: 3 | H36: 1.49 | I36: =IF(F36="S",1,IF(F36="A",0.8,IF(F36="B",0.55,IF(F36="C",0.3,IF(F36="D",0.25,0.25))))) -> 0.25 | J36: =MAX(H36,G36*I36) -> 1.49 | K36: =IFERROR(__xludf.DUMMYFUNCTION("GOOGLEFINANCE(""CURRENCY:USDXAF"")"),558.7654) -> 558.7654 | L36: =J36*K36 -> 832.56045 | M36: 790
A37: Kongo-Kinşasa | B37: Congo (the Democratic Republic of the) | C37: CD | D37: CDF | E37: 0.15 | F37: D | G37: 3 | H37: 1.49 | I37: =IF(F37="S",1,IF(F37="A",0.8,IF(F37="B",0.55,IF(F37="C",0.3,IF(F37="D",0.25,0.25))))) -> 0.25 | J37: =MAX(H37,G37*I37) -> 1.49 | K37: =IFERROR(__xludf.DUMMYFUNCTION("GOOGLEFINANCE(""CURRENCY:USDCDF"")"),2280.07117) -> 2280.0712 | L37: =J37*K37 -> 3397.306 | M37: 2900
A38: KostaRika | B38: Costa Rica | C38: CR | D38: CRC | E38: 0.5 | F38: D | G38: 3 | H38: 1.49 | I38: =IF(F38="S",1,IF(F38="A",0.8,IF(F38="B",0.55,IF(F38="C",0.3,IF(F38="D",0.25,0.25))))) -> 0.25 | J38: =MAX(H38,G38*I38) -> 1.49 | K38: =IFERROR(__xludf.DUMMYFUNCTION("GOOGLEFINANCE(""CURRENCY:USDCRC"")"),456.4117) -> 456.4117 | L38: =J38*K38 -> 680.05343 | M38: 649
A39: Côte d’Ivoire | B39: Côte d’Ivoire | C39: CI | D39: XOF | E39: 0.25 | F39: D | G39: 3 | H39: 1.49 | I39: =IF(F39="S",1,IF(F39="A",0.8,IF(F39="B",0.55,IF(F39="C",0.3,IF(F39="D",0.25,0.25))))) -> 0.25 | J39: =MAX(H39,G39*I39) -> 1.49 | K39: =IFERROR(__xludf.DUMMYFUNCTION("GOOGLEFINANCE(""CURRENCY:USDXOF"")"),558.7654) -> 558.7654 | L39: =J39*K39 -> 832.56045 | M39: 790
A40: Hırvatistan | B40: Croaita | C40: HR | D40: EUR | E40: 0.55 | F40: B | G40: 3 | H40: 1.49 | I40: =IF(F40="S",1,IF(F40="A",0.8,IF(F40="B",0.55,IF(F40="C",0.3,IF(F40="D",0.25,0.25))))) -> 0.55 | J40: =MAX(H40,G40*I40) -> 1.65 | K40: =IFERROR(__xludf.DUMMYFUNCTION("GOOGLEFINANCE(""CURRENCY:USDEUR"")"),0.8519) -> 0.8519 | L40: =J40*K40 -> 1.405635 | M40: 1.39
...

Sheet RoundingRules
A1: Rounding Rules / Editable Playbook
A3: Group | B3: Currency | C3: Logic | D3: Suggested Tiers | E3: Edit Note
A4: USD_99 | B4: USD | C4: Round to x.99 | D4: 0.99 / 1.99 / 2.99 / 3.99 / 4.99 | E4: Good for US-style pricing
A5: EUR_99 | B5: EUR | C5: Round to x.99 | D5: 0.99 / 1.99 / 2.99 / 3.99 / 4.99 | E5: EU premium-friendly
A6: TRY_TIERS | B6: TRY | C6: Fixed tier bucket | D6: 19 / 29 / 39 / 49 / 79 | E6: Test 29 vs 39 for conversion/revenue
A7: INR_TIERS | B7: INR | C7: Fixed tier bucket | D7: 29 / 49 / 99 | E7: Volume market
A8: BRL_90 | B8: BRL | C8: Round to x.90 | D8: 2.90 / 4.90 / 6.90 / 9.90
A9: IDR_000 | B9: IDR | C9: Nearest 1,000 | D9: 9,000 / 15,000 / 29,000
A10: JPY_00 | B10: JPY | C10: Nearest 100 | D10: 100 / 200 / 300 / 500
A11: KRW_000 | B11: KRW | C11: Nearest 1,000 | D11: 1,000 / 2,000 / 3,000 / 5,000
A12: VND_000 | B12: VND | C12: Nearest 1,000 | D12: 10,000 / 20,000 / 30,000

Sheet SourceNotes
A1: Source Notes / References
A3: Input | B3: Purpose | C3: Source / URL | D3: Refresh Cadence | E3: Notes
A4: PPP factor | B4: Relative local affordability input | C4: https://data.worldbank.org/indicator/PA.NUS.PPP | D4: Quarterly or before price updates | E4: Template values are starter estimates; replace with your chosen normalized PPP factors.
A5: FX rate | B5: Convert USD to local currency | C5: https://www.google.com/finance/ | D5: Before Play Console update | E5: In Google Sheets, use GOOGLEFINANCE formulas copied from PricingModel column N.
A6: Google Play pricing | B6: Check supported local prices and taxes | C6: https://support.google.com/googleplay/android-developer/ | D6: Before launch and major updates | E6: Play Console final local prices may differ due to tax/minimum price constraints.
A7: Competitor pricing | B7: Market adjustment sanity check | C7: Manual Play Store research | D7: Before launch | E7: Use Market Adj column to shift price after checking similar apps.

Sheet AB_TEST
A1: Date | B1: App | C1: Country | D1: Variant | E1: Price | F1: Currency | G1: Impressions | H1: Purchases | I1: Conversion | J1: Revenue | K1: ARPU | L1: Winner Note
A2: 46143 | B2: BLE Scanner | C2: TR | D2: A | E2: 39 | F2: TRY | G2: 1200 | H2: 48 | I2: =IFERROR(H2/G2,0) -> 0.04 | J2: =IFERROR(E2*H2,0) -> 1872 | K2: =IFERROR(J2/G2,0) -> 1.56 | L2: =IF(B2="","",IF(J2=MAX(SUMIFS($J$2:$J$200,$B$2:$B$200,B2,$C$2:$C$200,C2,$D$2:$D$200,"A"),SUMIFS($J$2:$J$200,$B$2:$B$200,B2,$C$2:$C$200,C2,$D$2:$D$200,"B")),"Current Winner",""))
A3: 46150 | B3: BLE Scanner | C3: TR | D3: B | E3: 29 | F3: TRY | G3: 1350 | H3: 78 | I3: =IFERROR(H3/G3,0) -> 0.057777778 | J3: =IFERROR(E3*H3,0) -> 2262 | K3: =IFERROR(J3/G3,0) -> 1.6755556 | L3: =IF(B3="","",IF(J3=MAX(SUMIFS($J$2:$J$200,$B$2:$B$200,B3,$C$2:$C$200,C3,$D$2:$D$200,"A"),SUMIFS($J$2:$J$200,$B$2:$B$200,B3,$C$2:$C$200,C3,$D$2:$D$200,"B")),"Current Winner","")) -> Current Winner
A4: 46143 | B4: Secure Vault | C4: TR | D4: A | E4: 49 | F4: TRY | G4: 900 | H4: 32 | I4: =IFERROR(H4/G4,0) -> 0.035555556 | J4: =IFERROR(E4*H4,0) -> 1568 | K4: =IFERROR(J4/G4,0) -> 1.7422222 | L4: =IF(B4="","",IF(J4=MAX(SUMIFS($J$2:$J$200,$B$2:$B$200,B4,$C$2:$C$200,C4,$D$2:$D$200,"A"),SUMIFS($J$2:$J$200,$B$2:$B$200,B4,$C$2:$C$200,C4,$D$2:$D$200,"B")),"Current Winner",""))
A5: 46150 | B5: Secure Vault | C5: TR | D5: B | E5: 39 | F5: TRY | G5: 960 | H5: 45 | I5: =IFERROR(H5/G5,0) -> 0.046875 | J5: =IFERROR(E5*H5,0) -> 1755 | K5: =IFERROR(J5/G5,0) -> 1.828125 | L5: =IF(B5="","",IF(J5=MAX(SUMIFS($J$2:$J$200,$B$2:$B$200,B5,$C$2:$C$200,C5,$D$2:$D$200,"A"),SUMIFS($J$2:$J$200,$B$2:$B$200,B5,$C$2:$C$200,C5,$D$2:$D$200,"B")),"Current Winner","")) -> Current Winner
A6: 46143 | B6: BLE Scanner | C6: IN | D6: A | E6: 49 | F6: INR | G6: 2400 | H6: 96 | I6: =IFERROR(H6/G6,0) -> 0.04 | J6: =IFERROR(E6*H6,0) -> 4704 | K6: =IFERROR(J6/G6,0) -> 1.96 | L6: =IF(B6="","",IF(J6=MAX(SUMIFS($J$2:$J$200,$B$2:$B$200,B6,$C$2:$C$200,C6,$D$2:$D$200,"A"),SUMIFS($J$2:$J$200,$B$2:$B$200,B6,$C$2:$C$200,C6,$D$2:$D$200,"B")),"Current Winner",""))
A7: 46150 | B7: BLE Scanner | C7: IN | D7: B | E7: 29 | F7: INR | G7: 2700 | H7: 168 | I7: =IFERROR(H7/G7,0) -> 0.062222222 | J7: =IFERROR(E7*H7,0) -> 4872 | K7: =IFERROR(J7/G7,0) -> 1.8044444 | L7: =IF(B7="","",IF(J7=MAX(SUMIFS($J$2:$J$200,$B$2:$B$200,B7,$C$2:$C$200,C7,$D$2:$D$200,"A"),SUMIFS($J$2:$J$200,$B$2:$B$200,B7,$C$2:$C$200,C7,$D$2:$D$200,"B")),"Current Winner","")) -> Current Winner
A8: 46143 | B8: Secure Vault | C8: BR | D8: A | E8: 6.9 | F8: BRL | G8: 760 | H8: 20 | I8: =IFERROR(H8/G8,0) -> 0.026315789 | J8: =IFERROR(E8*H8,0) -> 138 | K8: =IFERROR(J8/G8,0) -> 0.18157895 | L8: =IF(B8="","",IF(J8=MAX(SUMIFS($J$2:$J$200,$B$2:$B$200,B8,$C$2:$C$200,C8,$D$2:$D$200,"A"),SUMIFS($J$2:$J$200,$B$2:$B$200,B8,$C$2:$C$200,C8,$D$2:$D$200,"B")),"Current Winner",""))
